Workbook

Sheet 基本数据输入&测算结果
A3: 安徽电价区间 | B3: 0 | C3: 0.041666667 | D3: 0.083333333 | E3: 0.125 | F3: 0.16666667 | G3: 0.20833333 | H3: 0.25 | I3: 0.29166667 | J3: 0.33333333 | K3: 0.375 | L3: 0.41666667 | M3: 0.45833333 | N3: 0.5 | O3: 0.54166667 | P3: 0.58333333 | Q3: 0.625 | R3: 0.66666667 | S3: 0.70833333 | T3: 0.75 | U3: 0.79166667 | V3: 0.83333333 | W3: 0.875 | X3: 0.91666667 | Y3: 0.95833333
A4: 7-9月 | B4: 平 | C4: 平 | D4: 谷 | E4: 谷 | F4: 谷 | G4: 谷 | H4: 谷 | I4: 谷 | J4: 谷 | K4: 平 | L4: 平 | M4: 谷 | N4: 谷 | O4: 平 | P4: 平 | Q4: 平 | R4: 峰 | S4: 峰 | T4: 峰 | U4: 峰 | V4: 峰 | W4: 峰 | X4: 峰 | Y4: 峰
A5: 充放电策略 | B5: 待机 | C5: 待机 | D5: 充 | E5: 充 | F5: 充 | G5: 充 | H5: 充 | I5: 充 | J5: 充 | K5: 放 | L5: 放 | M5: 充 | N5: 充 | O5: 待机 | P5: 待机 | Q5: 待机 | R5: 放 | S5: 放 | T5: 放 | U5: 放 | V5: 放 | W5: 放 | X5: 放 | Y5: 放
A6: 1、12月 | B6: 谷 | C6: 谷 | D6: 谷 | E6: 谷 | F6: 谷 | G6: 谷 | H6: 平 | I6: 平 | J6: 平 | K6: 平 | L6: 平 | M6: 平 | N6: 谷 | O6: 谷 | P6: 平 | Q6: 峰 | R6: 峰 | S6: 峰 | T6: 峰 | U6: 峰 | V6: 峰 | W6: 峰 | X6: 峰 | Y6: 谷
A7: 充放电策略 | B7: 充 | C7: 充 | D7: 充 | E7: 充 | F7: 充 | G7: 充 | H7: 放 | I7: 放 | J7: 放 | K7: 放 | L7: 放 | M7: 放 | N7: 充 | O7: 充 | P7: 待机 | Q7: 放 | R7: 放 | S7: 放 | T7: 放 | U7: 放 | V7: 放 | W7: 放 | X7: 放 | Y7: 充
A8: 其他月份 | B8: 谷 | C8: 谷 | D8: 谷 | E8: 谷 | F8: 谷 | G8: 谷 | H8: 峰 | I8: 峰 | J8: 平 | K8: 平 | L8: 平 | M8: 谷 | N8: 谷 | O8: 谷 | P8: 平 | Q8: 平 | R8: 峰 | S8: 峰 | T8: 峰 | U8: 峰 | V8: 峰 | W8: 峰 | X8: 平 | Y8: 谷
A9: 充放电策略 | B9: 充 | C9: 充 | D9: 充 | E9: 充 | F9: 充 | G9: 充 | H9: 放 | I9: 放 | J9: 待机 | K9: 待机 | L9: 待机 | M9: 充 | N9: 充 | O9: 充 | P9: 待机 | Q9: 待机 | R9: 放 | S9: 放 | T9: 放 | U9: 放 | V9: 放 | W9: 放 | X9: 待机 | Y9: 充
A10: 7月15日-8月31日 | B10: 平 | C10: 平 | D10: 谷 | E10: 谷 | F10: 谷 | G10: 谷 | H10: 谷 | I10: 谷 | J10: 谷 | K10: 平 | L10: 平 | M10: 谷 | N10: 谷 | O10: 平 | P10: 平 | Q10: 平 | R10: 峰 | S10: 峰 | T10: 峰 | U10: 峰 | V10: 尖 | W10: 尖 | X10: 峰 | Y10: 峰
A11: 充放电策略 | B11: 待机 | C11: 待机 | D11: 充 | E11: 充 | F11: 充 | G11: 充 | H11: 充 | I11: 充 | J11: 充 | K11: 放 | L11: 放 | M11: 充 | N11: 充 | O11: 待机 | P11: 待机 | Q11: 待机 | R11: 放 | S11: 放 | T11: 放 | U11: 放 | V11: 放 | W11: 放 | X11: 放 | Y11: 放
A12: 12月15日-1月31日 | B12: 谷 | C12: 谷 | D12: 谷 | E12: 谷 | F12: 谷 | G12: 谷 | H12: 平 | I12: 平 | J12: 平 | K12: 平 | L12: 平 | M12: 平 | N12: 谷 | O12: 谷 | P12: 平 | Q12: 峰 | R12: 峰 | S12: 峰 | T12: 峰 | U12: 尖 | V12: 尖 | W12: 峰 | X12: 峰 | Y12: 谷
A13: 充放电策略 | B13: 充 | C13: 充 | D13: 充 | E13: 充 | F13: 充 | G13: 充 | H13: 放 | I13: 放 | J13: 放 | K13: 放 | L13: 放 | M13: 放 | N13: 充 | O13: 充 | P13: 待机 | Q13: 放 | R13: 放 | S13: 放 | T13: 放 | U13: 放 | V13: 放 | W13: 放 | X13: 放 | Y13: 充
B18: 基本信息输入 | F18: 满充率 | G18: 第一次充电 | H18: 第二次充电 | J18: 放电率 | K18: 第一次放电 | L18: 第二次放电 | N18: 充放次数 | Q18: 尖电价比例 | R18: 第一次放电尖电价比例 | S18: 第二次放电尖电价比例
B19: 变压器容量 | C19: 1315 | F19: 1月 | G19: =SUM('负荷数据&测算'!CU2:CU32)/31 -> 0.032258065 | H19: =SUM('负荷数据&测算'!CY2:CY32)/31 -> 0.032258065 | J19: 1月 | K19: =SUM('负荷数据&测算'!CW2:CW32)/31 -> 0.032258065 | L19: =SUM('负荷数据&测算'!DA2:DA32)/31 -> 0.032258065 | N19: 1月 | O19: =SUM('负荷数据&测算'!DB2:DB32)/31 -> 0.064516129 | Q19: 1月 | S19: =AVERAGE('负荷数据&测算'!DC2:DC32) -> 0.032258065
B20: 电池容量 | C20: 500 | F20: 2月 | G20: =SUM('负荷数据&测算'!CU33:CU60)/28 -> 0 | H20: =SUM('负荷数据&测算'!CY33:CY60)/28 -> 0 | J20: 2月 | K20: =SUM('负荷数据&测算'!CW33:CW60)/28 -> 0 | L20: =SUM('负荷数据&测算'!DA33:DA60)/28 -> 0 | N20: 2月 | O20: =SUM('负荷数据&测算'!DB33:DB60)/28 -> 0 | Q20: 2月
B21: 充放深度 | C21: 0.9 | F21: 3月 | G21: =SUM('负荷数据&测算'!CU61:CU91)/31 -> 0 | H21: =SUM('负荷数据&测算'!CY61:CY91)/31 -> 0 | J21: 3月 | K21: =SUM('负荷数据&测算'!CW61:CW91)/31 -> 0 | L21: =SUM('负荷数据&测算'!DA61:DA91)/31 -> 0 | N21: 3月 | O21: =SUM('负荷数据&测算'!DB61:DB91)/31 -> 0 | Q21: 3月
B22: 单边效率 | C22: 0.922 | F22: 4月 | G22: =SUM('负荷数据&测算'!CU92:CU121)/30 -> 0 | H22: =SUM('负荷数据&测算'!CY92:CY121)/30 -> 0 | J22: 4月 | K22: =SUM('负荷数据&测算'!CW92:CW121)/30 -> 0 | L22: =SUM('负荷数据&测算'!DA92:DA121)/30 -> 0 | N22: 4月 | O22: =SUM('负荷数据&测算'!DB92:DB121)/30 -> 0 | Q22: 4月
B23: 充电余量 | C23: =C19*0.2 -> 263 | F23: 5月 | G23: =SUM('负荷数据&测算'!CU122:CU152)/31 -> 0 | H23: =SUM('负荷数据&测算'!CY122:CY152)/31 -> 0 | J23: 5月 | K23: =SUM('负荷数据&测算'!CW122:CW152)/31 -> 0 | L23: =SUM('负荷数据&测算'!DA122:DA152)/31 -> 0 | N23: 5月 | O23: =SUM('负荷数据&测算'!DB122:DB152)/31 -> 0 | Q23: 5月
B24: 放电余量 | C24: 100 | F24: 6月 | G24: =SUM('负荷数据&测算'!CU153:CU182)/30 -> 0 | H24: =SUM('负荷数据&测算'!CY153:CY182)/30 -> 0 | J24: 6月 | K24: =SUM('负荷数据&测算'!CW153:CW182)/30 -> 0 | L24: =SUM('负荷数据&测算'!DA153:DA182)/30 -> 0 | N24: 6月 | O24: =SUM('负荷数据&测算'!DB153:DB182)/30 -> 0 | Q24: 6月
F25: 7月 | G25: =SUM('负荷数据&测算'!CU183:CU213)/31 -> 0 | H25: =SUM('负荷数据&测算'!CY183:CY213)/31 -> 0 | J25: 7月 | K25: =SUM('负荷数据&测算'!CW183:CW213)/31 -> 0 | L25: =SUM('负荷数据&测算'!DA182:DA212)/31 -> 0 | N25: 7月 | O25: =SUM('负荷数据&测算'!DB183:DB213)/31 -> 0 | Q25: 7月 | S25: =AVERAGE('负荷数据&测算'!DC183:DC213) -> 0
F26: 8月 | G26: =SUM('负荷数据&测算'!CU214:CU244)/31 -> 0 | H26: =SUM('负荷数据&测算'!CY214:CY244)/31 -> 0 | J26: 8月 | K26: =SUM('负荷数据&测算'!CW214:CW244)/31 -> 0 | L26: =SUM('负荷数据&测算'!DA214:DA244)/31 -> 0 | N26: 8月 | O26: =SUM('负荷数据&测算'!DB214:DB244)/31 -> 0 | Q26: 8月 | S26: =AVERAGE('负荷数据&测算'!DC214:DC244) -> 0
F27: 9月 | G27: =SUM('负荷数据&测算'!CU245:CU274)/30 -> 0 | H27: =SUM('负荷数据&测算'!CY245:CY274)/30 -> 0 | J27: 9月 | K27: =SUM('负荷数据&测算'!CW245:CW274)/30 -> 0 | L27: =SUM('负荷数据&测算'!DA245:DA274)/30 -> 0 | N27: 9月 | O27: =SUM('负荷数据&测算'!DB245:DB274)/30 -> 0 | Q27: 9月
F28: 10月 | G28: =SUM('负荷数据&测算'!CU275:CU305)/31 -> 0 | H28: =SUM('负荷数据&测算'!CY275:CY305)/31 -> 0 | J28: 10月 | K28: =SUM('负荷数据&测算'!CW275:CW305)/31 -> 0 | L28: =SUM('负荷数据&测算'!DA275:DA305)/31 -> 0 | N28: 10月 | O28: =SUM('负荷数据&测算'!DB275:DB305)/31 -> 0 | Q28: 10月
F29: 11月 | G29: =SUM('负荷数据&测算'!CU306:CU335)/30 -> 0 | H29: =SUM('负荷数据&测算'!CY306:CY335)/30 -> 0 | J29: 11月 | K29: =SUM('负荷数据&测算'!CW306:CW335)/30 -> 0 | L29: =SUM('负荷数据&测算'!DA306:DA335)/30 -> 0 | N29: 11月 | O29: =SUM('负荷数据&测算'!DB306:DB335)/30 -> 0 | Q29: 11月
F30: 12月 | G30: =SUM('负荷数据&测算'!CU336:CU366)/31 -> 0 | H30: =SUM('负荷数据&测算'!CY336:CY366)/31 -> 0 | J30: 12月 | K30: =SUM('负荷数据&测算'!CW336:CW366)/31 -> 0 | L30: =SUM('负荷数据&测算'!DA336:DA366)/31 -> 0 | N30: 12月 | O30: =SUM('负荷数据&测算'!DB336:DB366)/31 -> 0 | Q30: 12月 | S30: =AVERAGE('负荷数据&测算'!DC336:DC366) -> 0
N31: 年均 | O31: =IFERROR(AVERAGE(O19:O30),"数据不全") -> 0.0053763441 | Q31: 年均
N32: 天数 | O32: =O31/2*365 -> 0.9811828

Sheet 负荷数据&测算
A1: 时间 | B1: 0 | C1: =B1+15/60/24 -> 0.010416667 | D1: =C1+15/60/24 -> 0.020833333 | E1: =D1+15/60/24 -> 0.03125 | F1: =E1+15/60/24 -> 0.041666667 | G1: =F1+15/60/24 -> 0.052083333 | H1: =G1+15/60/24 -> 0.0625 | I1: =H1+15/60/24 -> 0.072916667 | J1: =I1+15/60/24 -> 0.083333333 | ... CS1: =CR1+15/60/24 -> 0.98958333 | CT1: 第一次可充电量 | CU1: 第一次满充率 | CV1: 第一次可放电量 | CW1: 第一次放电率 | CX1: 第二次可充电量 | CY1: 第二次满充率 | CZ1: 第二次可放电量 | DA1: 第二次放电率 | DB1: 充放电次数 | DC1: 第一次放电尖电价比例
A2: 2025-01-01 | B2: 317.6 | C2: 365.6 | D2: 364.8 | E2: 351.2 | F2: 340.8 | G2: 344.8 | H2: 342.4 | I2: 344 | J2: 336 | K2: 320.8 | L2: 312 | M2: 318.4 | N2: 320.8 | O2: 339.2 | P2: 356.8 | Q2: 353.6 | R2: 378.4 | S2: 357.6 | T2: 378.4 | U2: 334.4 | V2: 324 | W2: 331.2 | X2: 336.8 | Y2: 368 | Z2: 346.4 | AA2: 352 | AB2: 378.4 | AC2: 347.2 | AD2: 357.6 | AE2: 357.6 | AF2: 391.2 | AG2: 388 | AH2: 344.8 | AI2: 369.6 | AJ2: 344.8 | AK2: 347.2 | AL2: 356 | AM2: 363.2 | AN2: 432.8 | AO2: 389.6 | AP2: 384.8 | AQ2: 422.4 | AR2: 369.6 | AS2: 352.8 | AT2: 344 | AU2: 348 | AV2: 372.8 | AW2: 352 | AX2: 396.8 | AY2: 376 | AZ2: 369.6 | BA2: 364 | BB2: 314.4 | BC2: 324.8 | BD2: 314.4 | BE2: 322.4 | BF2: 338.4 | BG2: 321.6 | BH2: 334.4 | BI2: 333.6 | BJ2: 357.6 | BK2: 384.8 | BL2: 367.2 | BM2: 379.2 | BN2: 380 | BO2: 376.8 | BP2: 385.6 | BQ2: 368 | BR2: 344 | BS2: 362.4 | BT2: 334.4 | BU2: 340.8 | BV2: 332.8 | BW2: 377.6 | BX2: 366.4 | BY2: 410.4 | BZ2: 399.2 | CA2: 375.2 | CB2: 368 | CC2: 372 | CD2: 373.6 | CE2: 385.6 | CF2: 381.6 | CG2: 355.2 | CH2: 356 | CI2: 353.6 | CJ2: 363.2 | CK2: 324 | CL2: 321.6 | CM2: 327.2 | CN2: 307.2 | CO2: 308 | CP2: 300.8 | CQ2: 323.2 | CR2: 307.2 | CS2: 354.4 | CT2: =IFERROR(('基本数据输入&测算结果'!$C$19*7-AVERAGE(B2:Y2,CP2:CS2)*7-'基本数据输入&测算结果'!$C$23*7)/'基本数据输入&测算结果'!$C$21*'基本数据输入&测算结果'!$C$22,"无数据/数据缺失") -> 5105.0116 | CU2: =IF(CT2<0,0,IF(CT2="无数据/数据缺失",0%,IF(CT2>'基本数据输入&测算结果'!$C$20,100%,CT2/'基本数据输入&测算结果'!$C$20))) -> 1 | CV2: =IFERROR((AVERAGE(Z2:AW2)*6-'基本数据输入&测算结果'!$C$24*6)/'基本数据输入&测算结果'!$C$21/'基本数据输入&测算结果'!$C$22,"无数据/数据缺失") -> 1932.0318 | CW2: =IF(CV2<0,0,IF(CV2="无数据/数据缺失",0%,IF(CV2>'基本数据输入&测算结果'!$C$20*CU2,CU2,CV2/'基本数据输入&测算结果'!$C$20*CU2))) -> 1 | CX2: =IFERROR(('基本数据输入&测算结果'!$C$19*2-AVERAGE(AX2:BE2)*2-'基本数据输入&测算结果'!$C$23*2)/'基本数据输入&测算结果'!$C$21*'基本数据输入&测算结果'!$C$22,"无数据/数据缺失") -> 1442.8276 | CY2: =IF(CX2<0,0,IF(CX2="无数据/数据缺失",0%,IF(CX2>'基本数据输入&测算结果'!$C$20,100%,CX2/'基本数据输入&测算结果'!$C$20))) -> 1 | CZ2: =IFERROR((AVERAGE(BJ2:CO2)*8-'基本数据输入&测算结果'!$C$24*8)/'基本数据输入&测算结果'!$C$21/'基本数据输入&测算结果'!$C$22,"无数据/数据缺失") -> 2512.4126 | DA2: =IF(CZ2<0,0,IF(CZ2="无数据/数据缺失",0,IF('基本数据输入&测算结果'!$C$20*CY2>CZ2,CZ2/'基本数据输入&测算结果'!$C$20*CY2,CY2))) -> 1 | DB2: =MIN(CU2,CW2)+MIN(CY2,DA2) -> 2 | DC2: =IF(DA2=0,0,IF(AVERAGE(BZ2:CG2)*2>'基本数据输入&测算结果'!$C$20*DA2,100%,AVERAGE(BZ2:CG2)*2/('基本数据输入&测算结果'!$C$20*DA2))) -> 1
A3: 2025-01-02 | CT3: =IFERROR(('基本数据输入&测算结果'!$C$19*7-AVERAGE(B3:Y3,CP3:CS3)*7-'基本数据输入&测算结果'!$C$23*7)/'基本数据输入&测算结果'!$C$21*'基本数据输入&测算结果'!$C$22,"无数据/数据缺失") -> 无数据/数据缺失 | CU3: =IF(CT3<0,0,IF(CT3="无数据/数据缺失",0%,IF(CT3>'基本数据输入&测算结果'!$C$20,100%,CT3/'基本数据输入&测算结果'!$C$20))) -> 0 | CV3: =IFERROR((AVERAGE(Z3:AW3)*6-'基本数据输入&测算结果'!$C$24*6)/'基本数据输入&测算结果'!$C$21/'基本数据输入&测算结果'!$C$22,"无数据/数据缺失") -> 无数据/数据缺失 | CW3: =IF(CV3<0,0,IF(CV3="无数据/数据缺失",0%,IF(CV3>'基本数据输入&测算结果'!$C$20*CU3,CU3,CV3/'基本数据输入&测算结果'!$C$20*CU3))) -> 0 | CX3: =IFERROR(('基本数据输入&测算结果'!$C$19*2-AVERAGE(AX3:BE3)*2-'基本数据输入&测算结果'!$C$23*2)/'基本数据输入&测算结果'!$C$21*'基本数据输入&测算结果'!$C$22,"无数据/数据缺失") -> 无数据/数据缺失 | CY3: =IF(CX3<0,0,IF(CX3="无数据/数据缺失",0%,IF(CX3>'基本数据输入&测算结果'!$C$20,100%,CX3/'基本数据输入&测算结果'!$C$20))) -> 0 | CZ3: =IFERROR((AVERAGE(BJ3:CO3)*8-'基本数据输入&测算结果'!$C$24*8)/'基本数据输入&测算结果'!$C$21/'基本数据输入&测算结果'!$C$22,"无数据/数据缺失") -> 无数据/数据缺失 | DA3: =IF(CZ3<0,0,IF(CZ3="无数据/数据缺失",0,IF('基本数据输入&测算结果'!$C$20*CY3>CZ3,CZ3/'基本数据输入&测算结果'!$C$20*CY3,CY3))) -> 0 | DB3: =MIN(CU3,CW3)+MIN(CY3,DA3) -> 0 | DC3: =IF(DA3=0,0,IF(AVERAGE(BZ3:CG3)*2>'基本数据输入&测算结果'!$C$20*DA3,100%,AVERAGE(BZ3:CG3)*2/('基本数据输入&测算结果'!$C$20*DA3))) -> 0
A4: 2025-01-03 | CT4: =IFERROR(('基本数据输入&测算结果'!$C$19*7-AVERAGE(B4:Y4,CP4:CS4)*7-'基本数据输入&测算结果'!$C$23*7)/'基本数据输入&测算结果'!$C$21*'基本数据输入&测算结果'!$C$22,"无数据/数据缺失") -> 无数据/数据缺失 | CU4: =IF(CT4<0,0,IF(CT4="无数据/数据缺失",0%,IF(CT4>'基本数据输入&测算结果'!$C$20,100%,CT4/'基本数据输入&测算结果'!$C$20))) -> 0 | CV4: =IFERROR((AVERAGE(Z4:AW4)*6-'基本数据输入&测算结果'!$C$24*6)/'基本数据输入&测算结果'!$C$21/'基本数据输入&测算结果'!$C$22,"无数据/数据缺失") -> 无数据/数据缺失 | CW4: =IF(CV4<0,0,IF(CV4="无数据/数据缺失",0%,IF(CV4>'基本数据输入&测算结果'!$C$20*CU4,CU4,CV4/'基本数据输入&测算结果'!$C$20*CU4))) -> 0 | CX4: =IFERROR(('基本数据输入&测算结果'!$C$19*2-AVERAGE(AX4:BE4)*2-'基本数据输入&测算结果'!$C$23*2)/'基本数据输入&测算结果'!$C$21*'基本数据输入&测算结果'!$C$22,"无数据/数据缺失") -> 无数据/数据缺失 | CY4: =IF(CX4<0,0,IF(CX4="无数据/数据缺失",0%,IF(CX4>'基本数据输入&测算结果'!$C$20,100%,CX4/'基本数据输入&测算结果'!$C$20))) -> 0 | CZ4: =IFERROR((AVERAGE(BJ4:CO4)*8-'基本数据输入&测算结果'!$C$24*8)/'基本数据输入&测算结果'!$C$21/'基本数据输入&测算结果'!$C$22,"无数据/数据缺失") -> 无数据/数据缺失 | DA4: =IF(CZ4<0,0,IF(CZ4="无数据/数据缺失",0,IF('基本数据输入&测算结果'!$C$20*CY4>CZ4,CZ4/'基本数据输入&测算结果'!$C$20*CY4,CY4))) -> 0 | DB4: =MIN(CU4,CW4)+MIN(CY4,DA4) -> 0 | DC4: =IF(DA4=0,0,IF(AVERAGE(BZ4:CG4)*2>'基本数据输入&测算结果'!$C$20*DA4,100%,AVERAGE(BZ4:CG4)*2/('基本数据输入&测算结果'!$C$20*DA4))) -> 0
A5: 2025-01-04 | CT5: =IFERROR(('基本数据输入&测算结果'!$C$19*7-AVERAGE(B5:Y5,CP5:CS5)*7-'基本数据输入&测算结果'!$C$23*7)/'基本数据输入&测算结果'!$C$21*'基本数据输入&测算结果'!$C$22,"无数据/数据缺失") -> 无数据/数据缺失 | CU5: =IF(CT5<0,0,IF(CT5="无数据/数据缺失",0%,IF(CT5>'基本数据输入&测算结果'!$C$20,100%,CT5/'基本数据输入&测算结果'!$C$20))) -> 0 | CV5: =IFERROR((AVERAGE(Z5:AW5)*6-'基本数据输入&测算结果'!$C$24*6)/'基本数据输入&测算结果'!$C$21/'基本数据输入&测算结果'!$C$22,"无数据/数据缺失") -> 无数据/数据缺失 | CW5: =IF(CV5<0,0,IF(CV5="无数据/数据缺失",0%,IF(CV5>'基本数据输入&测算结果'!$C$20*CU5,CU5,CV5/'基本数据输入&测算结果'!$C$20*CU5))) -> 0 | CX5: =IFERROR(('基本数据输入&测算结果'!$C$19*2-AVERAGE(AX5:BE5)*2-'基本数据输入&测算结果'!$C$23*2)/'基本数据输入&测算结果'!$C$21*'基本数据输入&测算结果'!$C$22,"无数据/数据缺失") -> 无数据/数据缺失 | CY5: =IF(CX5<0,0,IF(CX5="无数据/数据缺失",0%,IF(CX5>'基本数据输入&测算结果'!$C$20,100%,CX5/'基本数据输入&测算结果'!$C$20))) -> 0 | CZ5: =IFERROR((AVERAGE(BJ5:CO5)*8-'基本数据输入&测算结果'!$C$24*8)/'基本数据输入&测算结果'!$C$21/'基本数据输入&测算结果'!$C$22,"无数据/数据缺失") -> 无数据/数据缺失 | DA5: =IF(CZ5<0,0,IF(CZ5="无数据/数据缺失",0,IF('基本数据输入&测算结果'!$C$20*CY5>CZ5,CZ5/'基本数据输入&测算结果'!$C$20*CY5,CY5))) -> 0 | DB5: =MIN(CU5,CW5)+MIN(CY5,DA5) -> 0 | DC5: =IF(DA5=0,0,IF(AVERAGE(BZ5:CG5)*2>'基本数据输入&测算结果'!$C$20*DA5,100%,AVERAGE(BZ5:CG5)*2/('基本数据输入&测算结果'!$C$20*DA5))) -> 0
A6: 2025-01-05 | CT6: =IFERROR(('基本数据输入&测算结果'!$C$19*7-AVERAGE(B6:Y6,CP6:CS6)*7-'基本数据输入&测算结果'!$C$23*7)/'基本数据输入&测算结果'!$C$21*'基本数据输入&测算结果'!$C$22,"无数据/数据缺失") -> 无数据/数据缺失 | CU6: =IF(CT6<0,0,IF(CT6="无数据/数据缺失",0%,IF(CT6>'基本数据输入&测算结果'!$C$20,100%,CT6/'基本数据输入&测算结果'!$C$20))) -> 0 | CV6: =IFERROR((AVERAGE(Z6:AW6)*6-'基本数据输入&测算结果'!$C$24*6)/'基本数据输入&测算结果'!$C$21/'基本数据输入&测算结果'!$C$22,"无数据/数据缺失") -> 无数据/数据缺失 | CW6: =IF(CV6<0,0,IF(CV6="无数据/数据缺失",0%,IF(CV6>'基本数据输入&测算结果'!$C$20*CU6,CU6,CV6/'基本数据输入&测算结果'!$C$20*CU6))) -> 0 | CX6: =IFERROR(('基本数据输入&测算结果'!$C$19*2-AVERAGE(AX6:BE6)*2-'基本数据输入&测算结果'!$C$23*2)/'基本数据输入&测算结果'!$C$21*'基本数据输入&测算结果'!$C$22,"无数据/数据缺失") -> 无数据/数据缺失 | CY6: =IF(CX6<0,0,IF(CX6="无数据/数据缺失",0%,IF(CX6>'基本数据输入&测算结果'!$C$20,100%,CX6/'基本数据输入&测算结果'!$C$20))) -> 0 | CZ6: =IFERROR((AVERAGE(BJ6:CO6)*8-'基本数据输入&测算结果'!$C$24*8)/'基本数据输入&测算结果'!$C$21/'基本数据输入&测算结果'!$C$22,"无数据/数据缺失") -> 无数据/数据缺失 | DA6: =IF(CZ6<0,0,IF(CZ6="无数据/数据缺失",0,IF('基本数据输入&测算结果'!$C$20*CY6>CZ6,CZ6/'基本数据输入&测算结果'!$C$20*CY6,CY6))) -> 0 | DB6: =MIN(CU6,CW6)+MIN(CY6,DA6) -> 0 | DC6: =IF(DA6=0,0,IF(AVERAGE(BZ6:CG6)*2>'基本数据输入&测算结果'!$C$20*DA6,100%,AVERAGE(BZ6:CG6)*2/('基本数据输入&测算结果'!$C$20*DA6))) -> 0
A7: 2025-01-06 | CT7: =IFERROR(('基本数据输入&测算结果'!$C$19*7-AVERAGE(B7:Y7,CP7:CS7)*7-'基本数据输入&测算结果'!$C$23*7)/'基本数据输入&测算结果'!$C$21*'基本数据输入&测算结果'!$C$22,"无数据/数据缺失") -> 无数据/数据缺失 | CU7: =IF(CT7<0,0,IF(CT7="无数据/数据缺失",0%,IF(CT7>'基本数据输入&测算结果'!$C$20,100%,CT7/'基本数据输入&测算结果'!$C$20))) -> 0 | CV7: =IFERROR((AVERAGE(Z7:AW7)*6-'基本数据输入&测算结果'!$C$24*6)/'基本数据输入&测算结果'!$C$21/'基本数据输入&测算结果'!$C$22,"无数据/数据缺失") -> 无数据/数据缺失 | CW7: =IF(CV7<0,0,IF(CV7="无数据/数据缺失",0%,IF(CV7>'基本数据输入&测算结果'!$C$20*CU7,CU7,CV7/'基本数据输入&测算结果'!$C$20*CU7))) -> 0 | CX7: =IFERROR(('基本数据输入&测算结果'!$C$19*2-AVERAGE(AX7:BE7)*2-'基本数据输入&测算结果'!$C$23*2)/'基本数据输入&测算结果'!$C$21*'基本数据输入&测算结果'!$C$22,"无数据/数据缺失") -> 无数据/数据缺失 | CY7: =IF(CX7<0,0,IF(CX7="无数据/数据缺失",0%,IF(CX7>'基本数据输入&测算结果'!$C$20,100%,CX7/'基本数据输入&测算结果'!$C$20))) -> 0 | CZ7: =IFERROR((AVERAGE(BJ7:CO7)*8-'基本数据输入&测算结果'!$C$24*8)/'基本数据输入&测算结果'!$C$21/'基本数据输入&测算结果'!$C$22,"无数据/数据缺失") -> 无数据/数据缺失 | DA7: =IF(CZ7<0,0,IF(CZ7="无数据/数据缺失",0,IF('基本数据输入&测算结果'!$C$20*CY7>CZ7,CZ7/'基本数据输入&测算结果'!$C$20*CY7,CY7))) -> 0 | DB7: =MIN(CU7,CW7)+MIN(CY7,DA7) -> 0 | DC7: =IF(DA7=0,0,IF(AVERAGE(BZ7:CG7)*2>'基本数据输入&测算结果'!$C$20*DA7,100%,AVERAGE(BZ7:CG7)*2/('基本数据输入&测算结果'!$C$20*DA7))) -> 0
A8: 2025-01-07 | CT8: =IFERROR(('基本数据输入&测算结果'!$C$19*7-AVERAGE(B8:Y8,CP8:CS8)*7-'基本数据输入&测算结果'!$C$23*7)/'基本数据输入&测算结果'!$C$21*'基本数据输入&测算结果'!$C$22,"无数据/数据缺失") -> 无数据/数据缺失 | CU8: =IF(CT8<0,0,IF(CT8="无数据/数据缺失",0%,IF(CT8>'基本数据输入&测算结果'!$C$20,100%,CT8/'基本数据输入&测算结果'!$C$20))) -> 0 | CV8: =IFERROR((AVERAGE(Z8:AW8)*6-'基本数据输入&测算结果'!$C$24*6)/'基本数据输入&测算结果'!$C$21/'基本数据输入&测算结果'!$C$22,"无数据/数据缺失") -> 无数据/数据缺失 | CW8: =IF(CV8<0,0,IF(CV8="无数据/数据缺失",0%,IF(CV8>'基本数据输入&测算结果'!$C$20*CU8,CU8,CV8/'基本数据输入&测算结果'!$C$20*CU8))) -> 0 | CX8: =IFERROR(('基本数据输入&测算结果'!$C$19*2-AVERAGE(AX8:BE8)*2-'基本数据输入&测算结果'!$C$23*2)/'基本数据输入&测算结果'!$C$21*'基本数据输入&测算结果'!$C$22,"无数据/数据缺失") -> 无数据/数据缺失 | CY8: =IF(CX8<0,0,IF(CX8="无数据/数据缺失",0%,IF(CX8>'基本数据输入&测算结果'!$C$20,100%,CX8/'基本数据输入&测算结果'!$C$20))) -> 0 | CZ8: =IFERROR((AVERAGE(BJ8:CO8)*8-'基本数据输入&测算结果'!$C$24*8)/'基本数据输入&测算结果'!$C$21/'基本数据输入&测算结果'!$C$22,"无数据/数据缺失") -> 无数据/数据缺失 | DA8: =IF(CZ8<0,0,IF(CZ8="无数据/数据缺失",0,IF('基本数据输入&测算结果'!$C$20*CY8>CZ8,CZ8/'基本数据输入&测算结果'!$C$20*CY8,CY8))) -> 0 | DB8: =MIN(CU8,CW8)+MIN(CY8,DA8) -> 0 | DC8: =IF(DA8=0,0,IF(AVERAGE(BZ8:CG8)*2>'基本数据输入&测算结果'!$C$20*DA8,100%,AVERAGE(BZ8:CG8)*2/('基本数据输入&测算结果'!$C$20*DA8))) -> 0
A9: 2025-01-08 | CT9: =IFERROR(('基本数据输入&测算结果'!$C$19*7-AVERAGE(B9:Y9,CP9:CS9)*7-'基本数据输入&测算结果'!$C$23*7)/'基本数据输入&测算结果'!$C$21*'基本数据输入&测算结果'!$C$22,"无数据/数据缺失") -> 无数据/数据缺失 | CU9: =IF(CT9<0,0,IF(CT9="无数据/数据缺失",0%,IF(CT9>'基本数据输入&测算结果'!$C$20,100%,CT9/'基本数据输入&测算结果'!$C$20))) -> 0 | CV9: =IFERROR((AVERAGE(Z9:AW9)*6-'基本数据输入&测算结果'!$C$24*6)/'基本数据输入&测算结果'!$C$21/'基本数据输入&测算结果'!$C$22,"无数据/数据缺失") -> 无数据/数据缺失 | CW9: =IF(CV9<0,0,IF(CV9="无数据/数据缺失",0%,IF(CV9>'基本数据输入&测算结果'!$C$20*CU9,CU9,CV9/'基本数据输入&测算结果'!$C$20*CU9))) -> 0 | CX9: =IFERROR(('基本数据输入&测算结果'!$C$19*2-AVERAGE(AX9:BE9)*2-'基本数据输入&测算结果'!$C$23*2)/'基本数据输入&测算结果'!$C$21*'基本数据输入&测算结果'!$C$22,"无数据/数据缺失") -> 无数据/数据缺失 | CY9: =IF(CX9<0,0,IF(CX9="无数据/数据缺失",0%,IF(CX9>'基本数据输入&测算结果'!$C$20,100%,CX9/'基本数据输入&测算结果'!$C$20))) -> 0 | CZ9: =IFERROR((AVERAGE(BJ9:CO9)*8-'基本数据输入&测算结果'!$C$24*8)/'基本数据输入&测算结果'!$C$21/'基本数据输入&测算结果'!$C$22,"无数据/数据缺失") -> 无数据/数据缺失 | DA9: =IF(CZ9<0,0,IF(CZ9="无数据/数据缺失",0,IF('基本数据输入&测算结果'!$C$20*CY9>CZ9,CZ9/'基本数据输入&测算结果'!$C$20*CY9,CY9))) -> 0 | DB9: =MIN(CU9,CW9)+MIN(CY9,DA9) -> 0 | DC9: =IF(DA9=0,0,IF(AVERAGE(BZ9:CG9)*2>'基本数据输入&测算结果'!$C$20*DA9,100%,AVERAGE(BZ9:CG9)*2/('基本数据输入&测算结果'!$C$20*DA9))) -> 0
A10: 2025-01-09 | CT10: =IFERROR(('基本数据输入&测算结果'!$C$19*7-AVERAGE(B10:Y10,CP10:CS10)*7-'基本数据输入&测算结果'!$C$23*7)/'基本数据输入&测算结果'!$C$21*'基本数据输入&测算结果'!$C$22,"无数据/数据缺失") -> 无数据/数据缺失 | CU10: =IF(CT10<0,0,IF(CT10="无数据/数据缺失",0%,IF(CT10>'基本数据输入&测算结果'!$C$20,100%,CT10/'基本数据输入&测算结果'!$C$20))) -> 0 | CV10: =IFERROR((AVERAGE(Z10:AW10)*6-'基本数据输入&测算结果'!$C$24*6)/'基本数据输入&测算结果'!$C$21/'基本数据输入&测算结果'!$C$22,"无数据/数据缺失") -> 无数据/数据缺失 | CW10: =IF(CV10<0,0,IF(CV10="无数据/数据缺失",0%,IF(CV10>'基本数据输入&测算结果'!$C$20*CU10,CU10,CV10/'基本数据输入&测算结果'!$C$20*CU10))) -> 0 | CX10: =IFERROR(('基本数据输入&测算结果'!$C$19*2-AVERAGE(AX10:BE10)*2-'基本数据输入&测算结果'!$C$23*2)/'基本数据输入&测算结果'!$C$21*'基本数据输入&测算结果'!$C$22,"无数据/数据缺失") -> 无数据/数据缺失 | CY10: =IF(CX10<0,0,IF(CX10="无数据/数据缺失",0%,IF(CX10>'基本数据输入&测算结果'!$C$20,100%,CX10/'基本数据输入&测算结果'!$C$20))) -> 0 | CZ10: =IFERROR((AVERAGE(BJ10:CO10)*8-'基本数据输入&测算结果'!$C$24*8)/'基本数据输入&测算结果'!$C$21/'基本数据输入&测算结果'!$C$22,"无数据/数据缺失") -> 无数据/数据缺失 | DA10: =IF(CZ10<0,0,IF(CZ10="无数据/数据缺失",0,IF('基本数据输入&测算结果'!$C$20*CY10>CZ10,CZ10/'基本数据输入&测算结果'!$C$20*CY10,CY10))) -> 0 | DB10: =MIN(CU10,CW10)+MIN(CY10,DA10) -> 0 | DC10: =IF(DA10=0,0,IF(AVERAGE(BZ10:CG10)*2>'基本数据输入&测算结果'!$C$20*DA10,100%,AVERAGE(BZ10:CG10)*2/('基本数据输入&测算结果'!$C$20*DA10))) -> 0
A11: 2025-01-10 | CT11: =IFERROR(('基本数据输入&测算结果'!$C$19*7-AVERAGE(B11:Y11,CP11:CS11)*7-'基本数据输入&测算结果'!$C$23*7)/'基本数据输入&测算结果'!$C$21*'基本数据输入&测算结果'!$C$22,"无数据/数据缺失") -> 无数据/数据缺失 | CU11: =IF(CT11<0,0,IF(CT11="无数据/数据缺失",0%,IF(CT11>'基本数据输入&测算结果'!$C$20,100%,CT11/'基本数据输入&测算结果'!$C$20))) -> 0 | CV11: =IFERROR((AVERAGE(Z11:AW11)*6-'基本数据输入&测算结果'!$C$24*6)/'基本数据输入&测算结果'!$C$21/'基本数据输入&测算结果'!$C$22,"无数据/数据缺失") -> 无数据/数据缺失 | CW11: =IF(CV11<0,0,IF(CV11="无数据/数据缺失",0%,IF(CV11>'基本数据输入&测算结果'!$C$20*CU11,CU11,CV11/'基本数据输入&测算结果'!$C$20*CU11))) -> 0 | CX11: =IFERROR(('基本数据输入&测算结果'!$C$19*2-AVERAGE(AX11:BE11)*2-'基本数据输入&测算结果'!$C$23*2)/'基本数据输入&测算结果'!$C$21*'基本数据输入&测算结果'!$C$22,"无数据/数据缺失") -> 无数据/数据缺失 | CY11: =IF(CX11<0,0,IF(CX11="无数据/数据缺失",0%,IF(CX11>'基本数据输入&测算结果'!$C$20,100%,CX11/'基本数据输入&测算结果'!$C$20))) -> 0 | CZ11: =IFERROR((AVERAGE(BJ11:CO11)*8-'基本数据输入&测算结果'!$C$24*8)/'基本数据输入&测算结果'!$C$21/'基本数据输入&测算结果'!$C$22,"无数据/数据缺失") -> 无数据/数据缺失 | DA11: =IF(CZ11<0,0,IF(CZ11="无数据/数据缺失",0,IF('基本数据输入&测算结果'!$C$20*CY11>CZ11,CZ11/'基本数据输入&测算结果'!$C$20*CY11,CY11))) -> 0 | DB11: =MIN(CU11,CW11)+MIN(CY11,DA11) -> 0 | DC11: =IF(DA11=0,0,IF(AVERAGE(BZ11:CG11)*2>'基本数据输入&测算结果'!$C$20*DA11,100%,AVERAGE(BZ11:CG11)*2/('基本数据输入&测算结果'!$C$20*DA11))) -> 0
A12: 2025-01-11 | CT12: =IFERROR(('基本数据输入&测算结果'!$C$19*7-AVERAGE(B12:Y12,CP12:CS12)*7-'基本数据输入&测算结果'!$C$23*7)/'基本数据输入&测算结果'!$C$21*'基本数据输入&测算结果'!$C$22,"无数据/数据缺失") -> 无数据/数据缺失 | CU12: =IF(CT12<0,0,IF(CT12="无数据/数据缺失",0%,IF(CT12>'基本数据输入&测算结果'!$C$20,100%,CT12/'基本数据输入&测算结果'!$C$20))) -> 0 | CV12: =IFERROR((AVERAGE(Z12:AW12)*6-'基本数据输入&测算结果'!$C$24*6)/'基本数据输入&测算结果'!$C$21/'基本数据输入&测算结果'!$C$22,"无数据/数据缺失") -> 无数据/数据缺失 | CW12: =IF(CV12<0,0,IF(CV12="无数据/数据缺失",0%,IF(CV12>'基本数据输入&测算结果'!$C$20*CU12,CU12,CV12/'基本数据输入&测算结果'!$C$20*CU12))) -> 0 | CX12: =IFERROR(('基本数据输入&测算结果'!$C$19*2-AVERAGE(AX12:BE12)*2-'基本数据输入&测算结果'!$C$23*2)/'基本数据输入&测算结果'!$C$21*'基本数据输入&测算结果'!$C$22,"无数据/数据缺失") -> 无数据/数据缺失 | CY12: =IF(CX12<0,0,IF(CX12="无数据/数据缺失",0%,IF(CX12>'基本数据输入&测算结果'!$C$20,100%,CX12/'基本数据输入&测算结果'!$C$20))) -> 0 | CZ12: =IFERROR((AVERAGE(BJ12:CO12)*8-'基本数据输入&测算结果'!$C$24*8)/'基本数据输入&测算结果'!$C$21/'基本数据输入&测算结果'!$C$22,"无数据/数据缺失") -> 无数据/数据缺失 | DA12: =IF(CZ12<0,0,IF(CZ12="无数据/数据缺失",0,IF('基本数据输入&测算结果'!$C$20*CY12>CZ12,CZ12/'基本数据输入&测算结果'!$C$20*CY12,CY12))) -> 0 | DB12: =MIN(CU12,CW12)+MIN(CY12,DA12) -> 0 | DC12: =IF(DA12=0,0,IF(AVERAGE(BZ12:CG12)*2>'基本数据输入&测算结果'!$C$20*DA12,100%,AVERAGE(BZ12:CG12)*2/('基本数据输入&测算结果'!$C$20*DA12))) -> 0
A13: 2025-01-12 | CT13: =IFERROR(('基本数据输入&测算结果'!$C$19*7-AVERAGE(B13:Y13,CP13:CS13)*7-'基本数据输入&测算结果'!$C$23*7)/'基本数据输入&测算结果'!$C$21*'基本数据输入&测算结果'!$C$22,"无数据/数据缺失") -> 无数据/数据缺失 | CU13: =IF(CT13<0,0,IF(CT13="无数据/数据缺失",0%,IF(CT13>'基本数据输入&测算结果'!$C$20,100%,CT13/'基本数据输入&测算结果'!$C$20))) -> 0 | CV13: =IFERROR((AVERAGE(Z13:AW13)*6-'基本数据输入&测算结果'!$C$24*6)/'基本数据输入&测算结果'!$C$21/'基本数据输入&测算结果'!$C$22,"无数据/数据缺失") -> 无数据/数据缺失 | CW13: =IF(CV13<0,0,IF(CV13="无数据/数据缺失",0%,IF(CV13>'基本数据输入&测算结果'!$C$20*CU13,CU13,CV13/'基本数据输入&测算结果'!$C$20*CU13))) -> 0 | CX13: =IFERROR(('基本数据输入&测算结果'!$C$19*2-AVERAGE(AX13:BE13)*2-'基本数据输入&测算结果'!$C$23*2)/'基本数据输入&测算结果'!$C$21*'基本数据输入&测算结果'!$C$22,"无数据/数据缺失") -> 无数据/数据缺失 | CY13: =IF(CX13<0,0,IF(CX13="无数据/数据缺失",0%,IF(CX13>'基本数据输入&测算结果'!$C$20,100%,CX13/'基本数据输入&测算结果'!$C$20))) -> 0 | CZ13: =IFERROR((AVERAGE(BJ13:CO13)*8-'基本数据输入&测算结果'!$C$24*8)/'基本数据输入&测算结果'!$C$21/'基本数据输入&测算结果'!$C$22,"无数据/数据缺失") -> 无数据/数据缺失 | DA13: =IF(CZ13<0,0,IF(CZ13="无数据/数据缺失",0,IF('基本数据输入&测算结果'!$C$20*CY13>CZ13,CZ13/'基本数据输入&测算结果'!$C$20*CY13,CY13))) -> 0 | DB13: =MIN(CU13,CW13)+MIN(CY13,DA13) -> 0 | DC13: =IF(DA13=0,0,IF(AVERAGE(BZ13:CG13)*2>'基本数据输入&测算结果'!$C$20*DA13,100%,AVERAGE(BZ13:CG13)*2/('基本数据输入&测算结果'!$C$20*DA13))) -> 0
A14: 2025-01-13 | CT14: =IFERROR(('基本数据输入&测算结果'!$C$19*7-AVERAGE(B14:Y14,CP14:CS14)*7-'基本数据输入&测算结果'!$C$23*7)/'基本数据输入&测算结果'!$C$21*'基本数据输入&测算结果'!$C$22,"无数据/数据缺失") -> 无数据/数据缺失 | CU14: =IF(CT14<0,0,IF(CT14="无数据/数据缺失",0%,IF(CT14>'基本数据输入&测算结果'!$C$20,100%,CT14/'基本数据输入&测算结果'!$C$20))) -> 0 | CV14: =IFERROR((AVERAGE(Z14:AW14)*6-'基本数据输入&测算结果'!$C$24*6)/'基本数据输入&测算结果'!$C$21/'基本数据输入&测算结果'!$C$22,"无数据/数据缺失") -> 无数据/数据缺失 | CW14: =IF(CV14<0,0,IF(CV14="无数据/数据缺失",0%,IF(CV14>'基本数据输入&测算结果'!$C$20*CU14,CU14,CV14/'基本数据输入&测算结果'!$C$20*CU14))) -> 0 | CX14: =IFERROR(('基本数据输入&测算结果'!$C$19*2-AVERAGE(AX14:BE14)*2-'基本数据输入&测算结果'!$C$23*2)/'基本数据输入&测算结果'!$C$21*'基本数据输入&测算结果'!$C$22,"无数据/数据缺失") -> 无数据/数据缺失 | CY14: =IF(CX14<0,0,IF(CX14="无数据/数据缺失",0%,IF(CX14>'基本数据输入&测算结果'!$C$20,100%,CX14/'基本数据输入&测算结果'!$C$20))) -> 0 | CZ14: =IFERROR((AVERAGE(BJ14:CO14)*8-'基本数据输入&测算结果'!$C$24*8)/'基本数据输入&测算结果'!$C$21/'基本数据输入&测算结果'!$C$22,"无数据/数据缺失") -> 无数据/数据缺失 | DA14: =IF(CZ14<0,0,IF(CZ14="无数据/数据缺失",0,IF('基本数据输入&测算结果'!$C$20*CY14>CZ14,CZ14/'基本数据输入&测算结果'!$C$20*CY14,CY14))) -> 0 | DB14: =MIN(CU14,CW14)+MIN(CY14,DA14) -> 0 | DC14: =IF(DA14=0,0,IF(AVERAGE(BZ14:CG14)*2>'基本数据输入&测算结果'!$C$20*DA14,100%,AVERAGE(BZ14:CG14)*2/('基本数据输入&测算结果'!$C$20*DA14))) -> 0
... A32: 2025-01-31 | CT32: =IFERROR(('基本数据输入&测算结果'!$C$19*7-AVERAGE(B32:Y32,CP32:CS32)*7-'基本数据输入&测算结果'!$C$23*7)/'基本数据输入&测算结果'!$C$21*'基本数据输入&测算结果'!$C$22,"无数据/数据缺失") -> 无数据/数据缺失 | CU32: =IF(CT32<0,0,IF(CT32="无数据/数据缺失",0%,IF(CT32>'基本数据输入&测算结果'!$C$20,100%,CT32/'基本数据输入&测算结果'!$C$20))) -> 0 | CV32: =IFERROR((AVERAGE(Z32:AW32)*6-'基本数据输入&测算结果'!$C$24*6)/'基本数据输入&测算结果'!$C$21/'基本数据输入&测算结果'!$C$22,"无数据/数据缺失") -> 无数据/数据缺失 | CW32: =IF(CV32<0,0,IF(CV32="无数据/数据缺失",0%,IF(CV32>'基本数据输入&测算结果'!$C$20*CU32,CU32,CV32/'基本数据输入&测算结果'!$C$20*CU32))) -> 0 | CX32: =IFERROR(('基本数据输入&测算结果'!$C$19*2-AVERAGE(AX32:BE32)*2-'基本数据输入&测算结果'!$C$23*2)/'基本数据输入&测算结果'!$C$21*'基本数据输入&测算结果'!$C$22,"无数据/数据缺失") -> 无数据/数据缺失 | CY32: =IF(CX32<0,0,IF(CX32="无数据/数据缺失",0%,IF(CX32>'基本数据输入&测算结果'!$C$20,100%,CX32/'基本数据输入&测算结果'!$C$20))) -> 0 | CZ32: =IFERROR((AVERAGE(BJ32:CO32)*8-'基本数据输入&测算结果'!$C$24*8)/'基本数据输入&测算结果'!$C$21/'基本数据输入&测算结果'!$C$22,"无数据/数据缺失") -> 无数据/数据缺失 | DA32: =IF(CZ32<0,0,IF(CZ32="无数据/数据缺失",0,IF('基本数据输入&测算结果'!$C$20*CY32>CZ32,CZ32/'基本数据输入&测算结果'!$C$20*CY32,CY32))) -> 0 | DB32: =MIN(CU32,CW32)+MIN(CY32,DA32) -> 0 | DC32: =IF(DA32=0,0,IF(AVERAGE(BZ32:CG32)*2>'基本数据输入&测算结果'!$C$20*DA32,100%,AVERAGE(BZ32:CG32)*2/('基本数据输入&测算结果'!$C$20*DA32))) -> 0
A33: 2025-02-01 | CT33: =IFERROR(('基本数据输入&测算结果'!$C$19*7-AVERAGE(B33:Y33,CP33:CS33)*7-'基本数据输入&测算结果'!$C$23*7)/'基本数据输入&测算结果'!$C$21*'基本数据输入&测算结果'!$C$22,"无数据/数据缺失") -> 无数据/数据缺失 | CU33: =IF(CT33<0,0,IF(CT33="无数据/数据缺失",0%,IF(CT33>'基本数据输入&测算结果'!$C$20,100%,CT33/'基本数据输入&测算结果'!$C$20))) -> 0 | CV33: =IFERROR((AVERAGE(Z33:AG33)*2-'基本数据输入&测算结果'!$C$24*2)/'基本数据输入&测算结果'!$C$21/'基本数据输入&测算结果'!$C$22,"无数据/数据缺失") -> 无数据/数据缺失 | CW33: =IF(CV33<0,0,IF(CV33="无数据/数据缺失",0%,IF(CV33>'基本数据输入&测算结果'!$C$20*CU33,CU33,CV33/'基本数据输入&测算结果'!$C$20*CU33))) -> 0 | CX33: =IFERROR(('基本数据输入&测算结果'!$C$19*3-AVERAGE(AT33:BE33)*3-'基本数据输入&测算结果'!$C$23*3)/'基本数据输入&测算结果'!$C$21*'基本数据输入&测算结果'!$C$22,"无数据/数据缺失") -> 无数据/数据缺失 | CY33: =IF(CX33<0,0,IF(CX33="无数据/数据缺失",0%,IF(CX33>'基本数据输入&测算结果'!$C$20,100%,CX33/'基本数据输入&测算结果'!$C$20))) -> 0 | CZ33: =IFERROR((AVERAGE(BN33:CK33)*6-'基本数据输入&测算结果'!$C$24*6)/'基本数据输入&测算结果'!$C$21/'基本数据输入&测算结果'!$C$22,"无数据/数据缺失") -> 无数据/数据缺失 | DA33: =IF(CZ33<0,0,IF(CZ33="无数据/数据缺失",0,IF('基本数据输入&测算结果'!$C$20*CY33>CZ33,CZ33/'基本数据输入&测算结果'!$C$20*CY33,CY33))) -> 0 | DB33: =MIN(CU33,CW33)+MIN(CY33,DA33) -> 0
A34: 2025-02-02 | CT34: =IFERROR(('基本数据输入&测算结果'!$C$19*7-AVERAGE(B34:Y34,CP34:CS34)*7-'基本数据输入&测算结果'!$C$23*7)/'基本数据输入&测算结果'!$C$21*'基本数据输入&测算结果'!$C$22,"无数据/数据缺失") -> 无数据/数据缺失 | CU34: =IF(CT34<0,0,IF(CT34="无数据/数据缺失",0%,IF(CT34>'基本数据输入&测算结果'!$C$20,100%,CT34/'基本数据输入&测算结果'!$C$20))) -> 0 | CV34: =IFERROR((AVERAGE(Z34:AG34)*2-'基本数据输入&测算结果'!$C$24*2)/'基本数据输入&测算结果'!$C$21/'基本数据输入&测算结果'!$C$22,"无数据/数据缺失") -> 无数据/数据缺失 | CW34: =IF(CV34<0,0,IF(CV34="无数据/数据缺失",0%,IF(CV34>'基本数据输入&测算结果'!$C$20*CU34,CU34,CV34/'基本数据输入&测算结果'!$C$20*CU34))) -> 0 | CX34: =IFERROR(('基本数据输入&测算结果'!$C$19*3-AVERAGE(AT34:BE34)*3-'基本数据输入&测算结果'!$C$23*3)/'基本数据输入&测算结果'!$C$21*'基本数据输入&测算结果'!$C$22,"无数据/数据缺失") -> 无数据/数据缺失 | CY34: =IF(CX34<0,0,IF(CX34="无数据/数据缺失",0%,IF(CX34>'基本数据输入&测算结果'!$C$20,100%,CX34/'基本数据输入&测算结果'!$C$20))) -> 0 | CZ34: =IFERROR((AVERAGE(BN34:CK34)*6-'基本数据输入&测算结果'!$C$24*6)/'基本数据输入&测算结果'!$C$21/'基本数据输入&测算结果'!$C$22,"无数据/数据缺失") -> 无数据/数据缺失 | DA34: =IF(CZ34<0,0,IF(CZ34="无数据/数据缺失",0,IF('基本数据输入&测算结果'!$C$20*CY34>CZ34,CZ34/'基本数据输入&测算结果'!$C$20*CY34,CY34))) -> 0 | DB34: =MIN(CU34,CW34)+MIN(CY34,DA34) -> 0
A35: 2025-02-03 | CT35: =IFERROR(('基本数据输入&测算结果'!$C$19*7-AVERAGE(B35:Y35,CP35:CS35)*7-'基本数据输入&测算结果'!$C$23*7)/'基本数据输入&测算结果'!$C$21*'基本数据输入&测算结果'!$C$22,"无数据/数据缺失") -> 无数据/数据缺失 | CU35: =IF(CT35<0,0,IF(CT35="无数据/数据缺失",0%,IF(CT35>'基本数据输入&测算结果'!$C$20,100%,CT35/'基本数据输入&测算结果'!$C$20))) -> 0 | CV35: =IFERROR((AVERAGE(Z35:AG35)*2-'基本数据输入&测算结果'!$C$24*2)/'基本数据输入&测算结果'!$C$21/'基本数据输入&测算结果'!$C$22,"无数据/数据缺失") -> 无数据/数据缺失 | CW35: =IF(CV35<0,0,IF(CV35="无数据/数据缺失",0%,IF(CV35>'基本数据输入&测算结果'!$C$20*CU35,CU35,CV35/'基本数据输入&测算结果'!$C$20*CU35))) -> 0 | CX35: =IFERROR(('基本数据输入&测算结果'!$C$19*3-AVERAGE(AT35:BE35)*3-'基本数据输入&测算结果'!$C$23*3)/'基本数据输入&测算结果'!$C$21*'基本数据输入&测算结果'!$C$22,"无数据/数据缺失") -> 无数据/数据缺失 | CY35: =IF(CX35<0,0,IF(CX35="无数据/数据缺失",0%,IF(CX35>'基本数据输入&测算结果'!$C$20,100%,CX35/'基本数据输入&测算结果'!$C$20))) -> 0 | CZ35: =IFERROR((AVERAGE(BN35:CK35)*6-'基本数据输入&测算结果'!$C$24*6)/'基本数据输入&测算结果'!$C$21/'基本数据输入&测算结果'!$C$22,"无数据/数据缺失") -> 无数据/数据缺失 | DA35: =IF(CZ35<0,0,IF(CZ35="无数据/数据缺失",0,IF('基本数据输入&测算结果'!$C$20*CY35>CZ35,CZ35/'基本数据输入&测算结果'!$C$20*CY35,CY35))) -> 0 | DB35: =MIN(CU35,CW35)+MIN(CY35,DA35) -> 0
A36: 2025-02-04 | CT36: =IFERROR(('基本数据输入&测算结果'!$C$19*7-AVERAGE(B36:Y36,CP36:CS36)*7-'基本数据输入&测算结果'!$C$23*7)/'基本数据输入&测算结果'!$C$21*'基本数据输入&测算结果'!$C$22,"无数据/数据缺失") -> 无数据/数据缺失 | CU36: =IF(CT36<0,0,IF(CT36="无数据/数据缺失",0%,IF(CT36>'基本数据输入&测算结果'!$C$20,100%,CT36/'基本数据输入&测算结果'!$C$20))) -> 0 | CV36: =IFERROR((AVERAGE(Z36:AG36)*2-'基本数据输入&测算结果'!$C$24*2)/'基本数据输入&测算结果'!$C$21/'基本数据输入&测算结果'!$C$22,"无数据/数据缺失") -> 无数据/数据缺失 | CW36: =IF(CV36<0,0,IF(CV36="无数据/数据缺失",0%,IF(CV36>'基本数据输入&测算结果'!$C$20*CU36,CU36,CV36/'基本数据输入&测算结果'!$C$20*CU36))) -> 0 | CX36: =IFERROR(('基本数据输入&测算结果'!$C$19*3-AVERAGE(AT36:BE36)*3-'基本数据输入&测算结果'!$C$23*3)/'基本数据输入&测算结果'!$C$21*'基本数据输入&测算结果'!$C$22,"无数据/数据缺失") -> 无数据/数据缺失 | CY36: =IF(CX36<0,0,IF(CX36="无数据/数据缺失",0%,IF(CX36>'基本数据输入&测算结果'!$C$20,100%,CX36/'基本数据输入&测算结果'!$C$20))) -> 0 | CZ36: =IFERROR((AVERAGE(BN36:CK36)*6-'基本数据输入&测算结果'!$C$24*6)/'基本数据输入&测算结果'!$C$21/'基本数据输入&测算结果'!$C$22,"无数据/数据缺失") -> 无数据/数据缺失 | DA36: =IF(CZ36<0,0,IF(CZ36="无数据/数据缺失",0,IF('基本数据输入&测算结果'!$C$20*CY36>CZ36,CZ36/'基本数据输入&测算结果'!$C$20*CY36,CY36))) -> 0 | DB36: =MIN(CU36,CW36)+MIN(CY36,DA36) -> 0
A37: 2025-02-05 | CT37: =IFERROR(('基本数据输入&测算结果'!$C$19*7-AVERAGE(B37:Y37,CP37:CS37)*7-'基本数据输入&测算结果'!$C$23*7)/'基本数据输入&测算结果'!$C$21*'基本数据输入&测算结果'!$C$22,"无数据/数据缺失") -> 无数据/数据缺失 | CU37: =IF(CT37<0,0,IF(CT37="无数据/数据缺失",0%,IF(CT37>'基本数据输入&测算结果'!$C$20,100%,CT37/'基本数据输入&测算结果'!$C$20))) -> 0 | CV37: =IFERROR((AVERAGE(Z37:AG37)*2-'基本数据输入&测算结果'!$C$24*2)/'基本数据输入&测算结果'!$C$21/'基本数据输入&测算结果'!$C$22,"无数据/数据缺失") -> 无数据/数据缺失 | CW37: =IF(CV37<0,0,IF(CV37="无数据/数据缺失",0%,IF(CV37>'基本数据输入&测算结果'!$C$20*CU37,CU37,CV37/'基本数据输入&测算结果'!$C$20*CU37))) -> 0 | CX37: =IFERROR(('基本数据输入&测算结果'!$C$19*3-AVERAGE(AT37:BE37)*3-'基本数据输入&测算结果'!$C$23*3)/'基本数据输入&测算结果'!$C$21*'基本数据输入&测算结果'!$C$22,"无数据/数据缺失") -> 无数据/数据缺失 | CY37: =IF(CX37<0,0,IF(CX37="无数据/数据缺失",0%,IF(CX37>'基本数据输入&测算结果'!$C$20,100%,CX37/'基本数据输入&测算结果'!$C$20))) -> 0 | CZ37: =IFERROR((AVERAGE(BN37:CK37)*6-'基本数据输入&测算结果'!$C$24*6)/'基本数据输入&测算结果'!$C$21/'基本数据输入&测算结果'!$C$22,"无数据/数据缺失") -> 无数据/数据缺失 | DA37: =IF(CZ37<0,0,IF(CZ37="无数据/数据缺失",0,IF('基本数据输入&测算结果'!$C$20*CY37>CZ37,CZ37/'基本数据输入&测算结果'!$C$20*CY37,CY37))) -> 0 | DB37: =MIN(CU37,CW37)+MIN(CY37,DA37) -> 0
A38: 2025-02-06 | CT38: =IFERROR(('基本数据输入&测算结果'!$C$19*7-AVERAGE(B38:Y38,CP38:CS38)*7-'基本数据输入&测算结果'!$C$23*7)/'基本数据输入&测算结果'!$C$21*'基本数据输入&测算结果'!$C$22,"无数据/数据缺失") -> 无数据/数据缺失 | CU38: =IF(CT38<0,0,IF(CT38="无数据/数据缺失",0%,IF(CT38>'基本数据输入&测算结果'!$C$20,100%,CT38/'基本数据输入&测算结果'!$C$20))) -> 0 | CV38: =IFERROR((AVERAGE(Z38:AG38)*2-'基本数据输入&测算结果'!$C$24*2)/'基本数据输入&测算结果'!$C$21/'基本数据输入&测算结果'!$C$22,"无数据/数据缺失") -> 无数据/数据缺失 | CW38: =IF(CV38<0,0,IF(CV38="无数据/数据缺失",0%,IF(CV38>'基本数据输入&测算结果'!$C$20*CU38,CU38,CV38/'基本数据输入&测算结果'!$C$20*CU38))) -> 0 | CX38: =IFERROR(('基本数据输入&测算结果'!$C$19*3-AVERAGE(AT38:BE38)*3-'基本数据输入&测算结果'!$C$23*3)/'基本数据输入&测算结果'!$C$21*'基本数据输入&测算结果'!$C$22,"无数据/数据缺失") -> 无数据/数据缺失 | CY38: =IF(CX38<0,0,IF(CX38="无数据/数据缺失",0%,IF(CX38>'基本数据输入&测算结果'!$C$20,100%,CX38/'基本数据输入&测算结果'!$C$20))) -> 0 | CZ38: =IFERROR((AVERAGE(BN38:CK38)*6-'基本数据输入&测算结果'!$C$24*6)/'基本数据输入&测算结果'!$C$21/'基本数据输入&测算结果'!$C$22,"无数据/数据缺失") -> 无数据/数据缺失 | DA38: =IF(CZ38<0,0,IF(CZ38="无数据/数据缺失",0,IF('基本数据输入&测算结果'!$C$20*CY38>CZ38,CZ38/'基本数据输入&测算结果'!$C$20*CY38,CY38))) -> 0 | DB38: =MIN(CU38,CW38)+MIN(CY38,DA38) -> 0
A39: 2025-02-07 | CT39: =IFERROR(('基本数据输入&测算结果'!$C$19*7-AVERAGE(B39:Y39,CP39:CS39)*7-'基本数据输入&测算结果'!$C$23*7)/'基本数据输入&测算结果'!$C$21*'基本数据输入&测算结果'!$C$22,"无数据/数据缺失") -> 无数据/数据缺失 | CU39: =IF(CT39<0,0,IF(CT39="无数据/数据缺失",0%,IF(CT39>'基本数据输入&测算结果'!$C$20,100%,CT39/'基本数据输入&测算结果'!$C$20))) -> 0 | CV39: =IFERROR((AVERAGE(Z39:AG39)*2-'基本数据输入&测算结果'!$C$24*2)/'基本数据输入&测算结果'!$C$21/'基本数据输入&测算结果'!$C$22,"无数据/数据缺失") -> 无数据/数据缺失 | CW39: =IF(CV39<0,0,IF(CV39="无数据/数据缺失",0%,IF(CV39>'基本数据输入&测算结果'!$C$20*CU39,CU39,CV39/'基本数据输入&测算结果'!$C$20*CU39))) -> 0 | CX39: =IFERROR(('基本数据输入&测算结果'!$C$19*3-AVERAGE(AT39:BE39)*3-'基本数据输入&测算结果'!$C$23*3)/'基本数据输入&测算结果'!$C$21*'基本数据输入&测算结果'!$C$22,"无数据/数据缺失") -> 无数据/数据缺失 | CY39: =IF(CX39<0,0,IF(CX39="无数据/数据缺失",0%,IF(CX39>'基本数据输入&测算结果'!$C$20,100%,CX39/'基本数据输入&测算结果'!$C$20))) -> 0 | CZ39: =IFERROR((AVERAGE(BN39:CK39)*6-'基本数据输入&测算结果'!$C$24*6)/'基本数据输入&测算结果'!$C$21/'基本数据输入&测算结果'!$C$22,"无数据/数据缺失") -> 无数据/数据缺失 | DA39: =IF(CZ39<0,0,IF(CZ39="无数据/数据缺失",0,IF('基本数据输入&测算结果'!$C$20*CY39>CZ39,CZ39/'基本数据输入&测算结果'!$C$20*CY39,CY39))) -> 0 | DB39: =MIN(CU39,CW39)+MIN(CY39,DA39) -> 0
A40: 2025-02-08 | CT40: =IFERROR(('基本数据输入&测算结果'!$C$19*7-AVERAGE(B40:Y40,CP40:CS40)*7-'基本数据输入&测算结果'!$C$23*7)/'基本数据输入&测算结果'!$C$21*'基本数据输入&测算结果'!$C$22,"无数据/数据缺失") -> 无数据/数据缺失 | CU40: =IF(CT40<0,0,IF(CT40="无数据/数据缺失",0%,IF(CT40>'基本数据输入&测算结果'!$C$20,100%,CT40/'基本数据输入&测算结果'!$C$20))) -> 0 | CV40: =IFERROR((AVERAGE(Z40:AG40)*2-'基本数据输入&测算结果'!$C$24*2)/'基本数据输入&测算结果'!$C$21/'基本数据输入&测算结果'!$C$22,"无数据/数据缺失") -> 无数据/数据缺失 | CW40: =IF(CV40<0,0,IF(CV40="无数据/数据缺失",0%,IF(CV40>'基本数据输入&测算结果'!$C$20*CU40,CU40,CV40/'基本数据输入&测算结果'!$C$20*CU40))) -> 0 | CX40: =IFERROR(('基本数据输入&测算结果'!$C$19*3-AVERAGE(AT40:BE40)*3-'基本数据输入&测算结果'!$C$23*3)/'基本数据输入&测算结果'!$C$21*'基本数据输入&测算结果'!$C$22,"无数据/数据缺失") -> 无数据/数据缺失 | CY40: =IF(CX40<0,0,IF(CX40="无数据/数据缺失",0%,IF(CX40>'基本数据输入&测算结果'!$C$20,100%,CX40/'基本数据输入&测算结果'!$C$20))) -> 0 | CZ40: =IFERROR((AVERAGE(BN40:CK40)*6-'基本数据输入&测算结果'!$C$24*6)/'基本数据输入&测算结果'!$C$21/'基本数据输入&测算结果'!$C$22,"无数据/数据缺失") -> 无数据/数据缺失 | DA40: =IF(CZ40<0,0,IF(CZ40="无数据/数据缺失",0,IF('基本数据输入&测算结果'!$C$20*CY40>CZ40,CZ40/'基本数据输入&测算结果'!$C$20*CY40,CY40))) -> 0 | DB40: =MIN(CU40,CW40)+MIN(CY40,DA40) -> 0
A41: 2025-02-09 | CT41: =IFERROR(('基本数据输入&测算结果'!$C$19*7-AVERAGE(B41:Y41,CP41:CS41)*7-'基本数据输入&测算结果'!$C$23*7)/'基本数据输入&测算结果'!$C$21*'基本数据输入&测算结果'!$C$22,"无数据/数据缺失") -> 无数据/数据缺失 | CU41: =IF(CT41<0,0,IF(CT41="无数据/数据缺失",0%,IF(CT41>'基本数据输入&测算结果'!$C$20,100%,CT41/'基本数据输入&测算结果'!$C$20))) -> 0 | CV41: =IFERROR((AVERAGE(Z41:AG41)*2-'基本数据输入&测算结果'!$C$24*2)/'基本数据输入&测算结果'!$C$21/'基本数据输入&测算结果'!$C$22,"无数据/数据缺失") -> 无数据/数据缺失 | CW41: =IF(CV41<0,0,IF(CV41="无数据/数据缺失",0%,IF(CV41>'基本数据输入&测算结果'!$C$20*CU41,CU41,CV41/'基本数据输入&测算结果'!$C$20*CU41))) -> 0 | CX41: =IFERROR(('基本数据输入&测算结果'!$C$19*3-AVERAGE(AT41:BE41)*3-'基本数据输入&测算结果'!$C$23*3)/'基本数据输入&测算结果'!$C$21*'基本数据输入&测算结果'!$C$22,"无数据/数据缺失") -> 无数据/数据缺失 | CY41: =IF(CX41<0,0,IF(CX41="无数据/数据缺失",0%,IF(CX41>'基本数据输入&测算结果'!$C$20,100%,CX41/'基本数据输入&测算结果'!$C$20))) -> 0 | CZ41: =IFERROR((AVERAGE(BN41:CK41)*6-'基本数据输入&测算结果'!$C$24*6)/'基本数据输入&测算结果'!$C$21/'基本数据输入&测算结果'!$C$22,"无数据/数据缺失") -> 无数据/数据缺失 | DA41: =IF(CZ41<0,0,IF(CZ41="无数据/数据缺失",0,IF('基本数据输入&测算结果'!$C$20*CY41>CZ41,CZ41/'基本数据输入&测算结果'!$C$20*CY41,CY41))) -> 0 | DB41: =MIN(CU41,CW41)+MIN(CY41,DA41) -> 0
A42: 2025-02-10 | CT42: =IFERROR(('基本数据输入&测算结果'!$C$19*7-AVERAGE(B42:Y42,CP42:CS42)*7-'基本数据输入&测算结果'!$C$23*7)/'基本数据输入&测算结果'!$C$21*'基本数据输入&测算结果'!$C$22,"无数据/数据缺失") -> 无数据/数据缺失 | CU42: =IF(CT42<0,0,IF(CT42="无数据/数据缺失",0%,IF(CT42>'基本数据输入&测算结果'!$C$20,100%,CT42/'基本数据输入&测算结果'!$C$20))) -> 0 | CV42: =IFERROR((AVERAGE(Z42:AG42)*2-'基本数据输入&测算结果'!$C$24*2)/'基本数据输入&测算结果'!$C$21/'基本数据输入&测算结果'!$C$22,"无数据/数据缺失") -> 无数据/数据缺失 | CW42: =IF(CV42<0,0,IF(CV42="无数据/数据缺失",0%,IF(CV42>'基本数据输入&测算结果'!$C$20*CU42,CU42,CV42/'基本数据输入&测算结果'!$C$20*CU42))) -> 0 | CX42: =IFERROR(('基本数据输入&测算结果'!$C$19*3-AVERAGE(AT42:BE42)*3-'基本数据输入&测算结果'!$C$23*3)/'基本数据输入&测算结果'!$C$21*'基本数据输入&测算结果'!$C$22,"无数据/数据缺失") -> 无数据/数据缺失 | CY42: =IF(CX42<0,0,IF(CX42="无数据/数据缺失",0%,IF(CX42>'基本数据输入&测算结果'!$C$20,100%,CX42/'基本数据输入&测算结果'!$C$20))) -> 0 | CZ42: =IFERROR((AVERAGE(BN42:CK42)*6-'基本数据输入&测算结果'!$C$24*6)/'基本数据输入&测算结果'!$C$21/'基本数据输入&测算结果'!$C$22,"无数据/数据缺失") -> 无数据/数据缺失 | DA42: =IF(CZ42<0,0,IF(CZ42="无数据/数据缺失",0,IF('基本数据输入&测算结果'!$C$20*CY42>CZ42,CZ42/'基本数据输入&测算结果'!$C$20*CY42,CY42))) -> 0 | DB42: =MIN(CU42,CW42)+MIN(CY42,DA42) -> 0
A43: 2025-02-11 | CT43: =IFERROR(('基本数据输入&测算结果'!$C$19*7-AVERAGE(B43:Y43,CP43:CS43)*7-'基本数据输入&测算结果'!$C$23*7)/'基本数据输入&测算结果'!$C$21*'基本数据输入&测算结果'!$C$22,"无数据/数据缺失") -> 无数据/数据缺失 | CU43: =IF(CT43<0,0,IF(CT43="无数据/数据缺失",0%,IF(CT43>'基本数据输入&测算结果'!$C$20,100%,CT43/'基本数据输入&测算结果'!$C$20))) -> 0 | CV43: =IFERROR((AVERAGE(Z43:AG43)*2-'基本数据输入&测算结果'!$C$24*2)/'基本数据输入&测算结果'!$C$21/'基本数据输入&测算结果'!$C$22,"无数据/数据缺失") -> 无数据/数据缺失 | CW43: =IF(CV43<0,0,IF(CV43="无数据/数据缺失",0%,IF(CV43>'基本数据输入&测算结果'!$C$20*CU43,CU43,CV43/'基本数据输入&测算结果'!$C$20*CU43))) -> 0 | CX43: =IFERROR(('基本数据输入&测算结果'!$C$19*3-AVERAGE(AT43:BE43)*3-'基本数据输入&测算结果'!$C$23*3)/'基本数据输入&测算结果'!$C$21*'基本数据输入&测算结果'!$C$22,"无数据/数据缺失") -> 无数据/数据缺失 | CY43: =IF(CX43<0,0,IF(CX43="无数据/数据缺失",0%,IF(CX43>'基本数据输入&测算结果'!$C$20,100%,CX43/'基本数据输入&测算结果'!$C$20))) -> 0 | CZ43: =IFERROR((AVERAGE(BN43:CK43)*6-'基本数据输入&测算结果'!$C$24*6)/'基本数据输入&测算结果'!$C$21/'基本数据输入&测算结果'!$C$22,"无数据/数据缺失") -> 无数据/数据缺失 | DA43: =IF(CZ43<0,0,IF(CZ43="无数据/数据缺失",0,IF('基本数据输入&测算结果'!$C$20*CY43>CZ43,CZ43/'基本数据输入&测算结果'!$C$20*CY43,CY43))) -> 0 | DB43: =MIN(CU43,CW43)+MIN(CY43,DA43) -> 0
A44: 2025-02-12 | CT44: =IFERROR(('基本数据输入&测算结果'!$C$19*7-AVERAGE(B44:Y44,CP44:CS44)*7-'基本数据输入&测算结果'!$C$23*7)/'基本数据输入&测算结果'!$C$21*'基本数据输入&测算结果'!$C$22,"无数据/数据缺失") -> 无数据/数据缺失 | CU44: =IF(CT44<0,0,IF(CT44="无数据/数据缺失",0%,IF(CT44>'基本数据输入&测算结果'!$C$20,100%,CT44/'基本数据输入&测算结果'!$C$20))) -> 0 | CV44: =IFERROR((AVERAGE(Z44:AG44)*2-'基本数据输入&测算结果'!$C$24*2)/'基本数据输入&测算结果'!$C$21/'基本数据输入&测算结果'!$C$22,"无数据/数据缺失") -> 无数据/数据缺失 | CW44: =IF(CV44<0,0,IF(CV44="无数据/数据缺失",0%,IF(CV44>'基本数据输入&测算结果'!$C$20*CU44,CU44,CV44/'基本数据输入&测算结果'!$C$20*CU44))) -> 0 | CX44: =IFERROR(('基本数据输入&测算结果'!$C$19*3-AVERAGE(AT44:BE44)*3-'基本数据输入&测算结果'!$C$23*3)/'基本数据输入&测算结果'!$C$21*'基本数据输入&测算结果'!$C$22,"无数据/数据缺失") -> 无数据/数据缺失 | CY44: =IF(CX44<0,0,IF(CX44="无数据/数据缺失",0%,IF(CX44>'基本数据输入&测算结果'!$C$20,100%,CX44/'基本数据输入&测算结果'!$C$20))) -> 0 | CZ44: =IFERROR((AVERAGE(BN44:CK44)*6-'基本数据输入&测算结果'!$C$24*6)/'基本数据输入&测算结果'!$C$21/'基本数据输入&测算结果'!$C$22,"无数据/数据缺失") -> 无数据/数据缺失 | DA44: =IF(CZ44<0,0,IF(CZ44="无数据/数据缺失",0,IF('基本数据输入&测算结果'!$C$20*CY44>CZ44,CZ44/'基本数据输入&测算结果'!$C$20*CY44,CY44))) -> 0 | DB44: =MIN(CU44,CW44)+MIN(CY44,DA44) -> 0
... A182: 2025-06-30 | CT182: =IFERROR(('基本数据输入&测算结果'!$C$19*7-AVERAGE(B182:Y182,CP182:CS182)*7-'基本数据输入&测算结果'!$C$23*7)/'基本数据输入&测算结果'!$C$21*'基本数据输入&测算结果'!$C$22,"无数据/数据缺失") -> 无数据/数据缺失 | CU182: =IF(CT182<0,0,IF(CT182="无数据/数据缺失",0%,IF(CT182>'基本数据输入&测算结果'!$C$20,100%,CT182/'基本数据输入&测算结果'!$C$20))) -> 0 | CV182: =IFERROR((AVERAGE(Z182:AG182)*2-'基本数据输入&测算结果'!$C$24*2)/'基本数据输入&测算结果'!$C$21/'基本数据输入&测算结果'!$C$22,"无数据/数据缺失") -> 无数据/数据缺失 | CW182: =IF(CV182<0,0,IF(CV182="无数据/数据缺失",0%,IF(CV182>'基本数据输入&测算结果'!$C$20*CU182,CU182,CV182/'基本数据输入&测算结果'!$C$20*CU182))) -> 0 | CX182: =IFERROR(('基本数据输入&测算结果'!$C$19*3-AVERAGE(AT182:BE182)*3-'基本数据输入&测算结果'!$C$23*3)/'基本数据输入&测算结果'!$C$21*'基本数据输入&测算结果'!$C$22,"无数据/数据缺失") -> 无数据/数据缺失 | CY182: =IF(CX182<0,0,IF(CX182="无数据/数据缺失",0%,IF(CX182>'基本数据输入&测算结果'!$C$20,100%,CX182/'基本数据输入&测算结果'!$C$20))) -> 0 | CZ182: =IFERROR((AVERAGE(BN182:CK182)*6-'基本数据输入&测算结果'!$C$24*6)/'基本数据输入&测算结果'!$C$21/'基本数据输入&测算结果'!$C$22,"无数据/数据缺失") -> 无数据/数据缺失 | DA182: =IF(CZ182<0,0,IF(CZ182="无数据/数据缺失",0,IF('基本数据输入&测算结果'!$C$20*CY182>CZ182,CZ182/'基本数据输入&测算结果'!$C$20*CY182,CY182))) -> 0 | DB182: =MIN(CU182,CW182)+MIN(CY182,DA182) -> 0
A183: 2025-07-01 | CT183: =IFERROR(('基本数据输入&测算结果'!$C$19*7-AVERAGE(J183:AK183)*7-'基本数据输入&测算结果'!$C$23*7)/'基本数据输入&测算结果'!$C$21*'基本数据输入&测算结果'!$C$22,"无数据/数据缺失") -> 无数据/数据缺失 | CU183: =IF(CT183<0,0,IF(CT183="无数据/数据缺失",0%,IF(CT183>'基本数据输入&测算结果'!$C$20,100%,CT183/'基本数据输入&测算结果'!$C$20))) -> 0 | CV183: =IFERROR((AVERAGE(AL183:AS183)*2-'基本数据输入&测算结果'!$C$24*2)/'基本数据输入&测算结果'!$C$21/'基本数据输入&测算结果'!$C$22,"无数据/数据缺失") -> 无数据/数据缺失 | CW183: =IF(CV183<0,0,IF(CV183="无数据/数据缺失",0%,IF(CV183>'基本数据输入&测算结果'!$C$20*CU183,CU183,CV183/'基本数据输入&测算结果'!$C$20*CU183))) -> 0 | CX183: =IFERROR(('基本数据输入&测算结果'!$C$19*2-AVERAGE(AT183:BA183)*2-'基本数据输入&测算结果'!$C$23*2)/'基本数据输入&测算结果'!$C$21*'基本数据输入&测算结果'!$C$22,"无数据/数据缺失") -> 无数据/数据缺失 | CY183: =IF(CX183<0,0,IF(CX183="无数据/数据缺失",0%,IF(CX183>'基本数据输入&测算结果'!$C$20,100%,CX183/'基本数据输入&测算结果'!$C$20))) -> 0 | CZ183: =IFERROR((AVERAGE(BN183:CS183)*8-'基本数据输入&测算结果'!$C$24*8)/'基本数据输入&测算结果'!$C$21/'基本数据输入&测算结果'!$C$22,"无数据/数据缺失") -> 无数据/数据缺失 | DA183: =IF(CZ183<0,0,IF(CZ183="无数据/数据缺失",0,IF('基本数据输入&测算结果'!$C$20*CY183>CZ183,CZ183/'基本数据输入&测算结果'!$C$20*CY183,CY183))) -> 0 | DB183: =MIN(CU183,CW183)+MIN(CY183,DA183) -> 0
A184: 2025-07-02 | CT184: =IFERROR(('基本数据输入&测算结果'!$C$19*7-AVERAGE(J184:AK184)*7-'基本数据输入&测算结果'!$C$23*7)/'基本数据输入&测算结果'!$C$21*'基本数据输入&测算结果'!$C$22,"无数据/数据缺失") -> 无数据/数据缺失 | CU184: =IF(CT184<0,0,IF(CT184="无数据/数据缺失",0%,IF(CT184>'基本数据输入&测算结果'!$C$20,100%,CT184/'基本数据输入&测算结果'!$C$20))) -> 0 | CV184: =IFERROR((AVERAGE(AL184:AS184)*2-'基本数据输入&测算结果'!$C$24*2)/'基本数据输入&测算结果'!$C$21/'基本数据输入&测算结果'!$C$22,"无数据/数据缺失") -> 无数据/数据缺失 | CW184: =IF(CV184<0,0,IF(CV184="无数据/数据缺失",0%,IF(CV184>'基本数据输入&测算结果'!$C$20*CU184,CU184,CV184/'基本数据输入&测算结果'!$C$20*CU184))) -> 0 | CX184: =IFERROR(('基本数据输入&测算结果'!$C$19*2-AVERAGE(AT184:BA184)*2-'基本数据输入&测算结果'!$C$23*2)/'基本数据输入&测算结果'!$C$21*'基本数据输入&测算结果'!$C$22,"无数据/数据缺失") -> 无数据/数据缺失 | CY184: =IF(CX184<0,0,IF(CX184="无数据/数据缺失",0%,IF(CX184>'基本数据输入&测算结果'!$C$20,100%,CX184/'基本数据输入&测算结果'!$C$20))) -> 0 | CZ184: =IFERROR((AVERAGE(BN184:CS184)*8-'基本数据输入&测算结果'!$C$24*8)/'基本数据输入&测算结果'!$C$21/'基本数据输入&测算结果'!$C$22,"无数据/数据缺失") -> 无数据/数据缺失 | DA184: =IF(CZ184<0,0,IF(CZ184="无数据/数据缺失",0,IF('基本数据输入&测算结果'!$C$20*CY184>CZ184,CZ184/'基本数据输入&测算结果'!$C$20*CY184,CY184))) -> 0 | DB184: =MIN(CU184,CW184)+MIN(CY184,DA184) -> 0
A185: 2025-07-03 | CT185: =IFERROR(('基本数据输入&测算结果'!$C$19*7-AVERAGE(J185:AK185)*7-'基本数据输入&测算结果'!$C$23*7)/'基本数据输入&测算结果'!$C$21*'基本数据输入&测算结果'!$C$22,"无数据/数据缺失") -> 无数据/数据缺失 | CU185: =IF(CT185<0,0,IF(CT185="无数据/数据缺失",0%,IF(CT185>'基本数据输入&测算结果'!$C$20,100%,CT185/'基本数据输入&测算结果'!$C$20))) -> 0 | CV185: =IFERROR((AVERAGE(AL185:AS185)*2-'基本数据输入&测算结果'!$C$24*2)/'基本数据输入&测算结果'!$C$21/'基本数据输入&测算结果'!$C$22,"无数据/数据缺失") -> 无数据/数据缺失 | CW185: =IF(CV185<0,0,IF(CV185="无数据/数据缺失",0%,IF(CV185>'基本数据输入&测算结果'!$C$20*CU185,CU185,CV185/'基本数据输入&测算结果'!$C$20*CU185))) -> 0 | CX185: =IFERROR(('基本数据输入&测算结果'!$C$19*2-AVERAGE(AT185:BA185)*2-'基本数据输入&测算结果'!$C$23*2)/'基本数据输入&测算结果'!$C$21*'基本数据输入&测算结果'!$C$22,"无数据/数据缺失") -> 无数据/数据缺失 | CY185: =IF(CX185<0,0,IF(CX185="无数据/数据缺失",0%,IF(CX185>'基本数据输入&测算结果'!$C$20,100%,CX185/'基本数据输入&测算结果'!$C$20))) -> 0 | CZ185: =IFERROR((AVERAGE(BN185:CS185)*8-'基本数据输入&测算结果'!$C$24*8)/'基本数据输入&测算结果'!$C$21/'基本数据输入&测算结果'!$C$22,"无数据/数据缺失") -> 无数据/数据缺失 | DA185: =IF(CZ185<0,0,IF(CZ185="无数据/数据缺失",0,IF('基本数据输入&测算结果'!$C$20*CY185>CZ185,CZ185/'基本数据输入&测算结果'!$C$20*CY185,CY185))) -> 0 | DB185: =MIN(CU185,CW185)+MIN(CY185,DA185) -> 0
A186: 2025-07-04 | CT186: =IFERROR(('基本数据输入&测算结果'!$C$19*7-AVERAGE(J186:AK186)*7-'基本数据输入&测算结果'!$C$23*7)/'基本数据输入&测算结果'!$C$21*'基本数据输入&测算结果'!$C$22,"无数据/数据缺失") -> 无数据/数据缺失 | CU186: =IF(CT186<0,0,IF(CT186="无数据/数据缺失",0%,IF(CT186>'基本数据输入&测算结果'!$C$20,100%,CT186/'基本数据输入&测算结果'!$C$20))) -> 0 | CV186: =IFERROR((AVERAGE(AL186:AS186)*2-'基本数据输入&测算结果'!$C$24*2)/'基本数据输入&测算结果'!$C$21/'基本数据输入&测算结果'!$C$22,"无数据/数据缺失") -> 无数据/数据缺失 | CW186: =IF(CV186<0,0,IF(CV186="无数据/数据缺失",0%,IF(CV186>'基本数据输入&测算结果'!$C$20*CU186,CU186,CV186/'基本数据输入&测算结果'!$C$20*CU186))) -> 0 | CX186: =IFERROR(('基本数据输入&测算结果'!$C$19*2-AVERAGE(AT186:BA186)*2-'基本数据输入&测算结果'!$C$23*2)/'基本数据输入&测算结果'!$C$21*'基本数据输入&测算结果'!$C$22,"无数据/数据缺失") -> 无数据/数据缺失 | CY186: =IF(CX186<0,0,IF(CX186="无数据/数据缺失",0%,IF(CX186>'基本数据输入&测算结果'!$C$20,100%,CX186/'基本数据输入&测算结果'!$C$20))) -> 0 | CZ186: =IFERROR((AVERAGE(BN186:CS186)*8-'基本数据输入&测算结果'!$C$24*8)/'基本数据输入&测算结果'!$C$21/'基本数据输入&测算结果'!$C$22,"无数据/数据缺失") -> 无数据/数据缺失 | DA186: =IF(CZ186<0,0,IF(CZ186="无数据/数据缺失",0,IF('基本数据输入&测算结果'!$C$20*CY186>CZ186,CZ186/'基本数据输入&测算结果'!$C$20*CY186,CY186))) -> 0 | DB186: =MIN(CU186,CW186)+MIN(CY186,DA186) -> 0
A187: 2025-07-05 | CT187: =IFERROR(('基本数据输入&测算结果'!$C$19*7-AVERAGE(J187:AK187)*7-'基本数据输入&测算结果'!$C$23*7)/'基本数据输入&测算结果'!$C$21*'基本数据输入&测算结果'!$C$22,"无数据/数据缺失") -> 无数据/数据缺失 | CU187: =IF(CT187<0,0,IF(CT187="无数据/数据缺失",0%,IF(CT187>'基本数据输入&测算结果'!$C$20,100%,CT187/'基本数据输入&测算结果'!$C$20))) -> 0 | CV187: =IFERROR((AVERAGE(AL187:AS187)*2-'基本数据输入&测算结果'!$C$24*2)/'基本数据输入&测算结果'!$C$21/'基本数据输入&测算结果'!$C$22,"无数据/数据缺失") -> 无数据/数据缺失 | CW187: =IF(CV187<0,0,IF(CV187="无数据/数据缺失",0%,IF(CV187>'基本数据输入&测算结果'!$C$20*CU187,CU187,CV187/'基本数据输入&测算结果'!$C$20*CU187))) -> 0 | CX187: =IFERROR(('基本数据输入&测算结果'!$C$19*2-AVERAGE(AT187:BA187)*2-'基本数据输入&测算结果'!$C$23*2)/'基本数据输入&测算结果'!$C$21*'基本数据输入&测算结果'!$C$22,"无数据/数据缺失") -> 无数据/数据缺失 | CY187: =IF(CX187<0,0,IF(CX187="无数据/数据缺失",0%,IF(CX187>'基本数据输入&测算结果'!$C$20,100%,CX187/'基本数据输入&测算结果'!$C$20))) -> 0 | CZ187: =IFERROR((AVERAGE(BN187:CS187)*8-'基本数据输入&测算结果'!$C$24*8)/'基本数据输入&测算结果'!$C$21/'基本数据输入&测算结果'!$C$22,"无数据/数据缺失") -> 无数据/数据缺失 | DA187: =IF(CZ187<0,0,IF(CZ187="无数据/数据缺失",0,IF('基本数据输入&测算结果'!$C$20*CY187>CZ187,CZ187/'基本数据输入&测算结果'!$C$20*CY187,CY187))) -> 0 | DB187: =MIN(CU187,CW187)+MIN(CY187,DA187) -> 0
A188: 2025-07-06 | CT188: =IFERROR(('基本数据输入&测算结果'!$C$19*7-AVERAGE(J188:AK188)*7-'基本数据输入&测算结果'!$C$23*7)/'基本数据输入&测算结果'!$C$21*'基本数据输入&测算结果'!$C$22,"无数据/数据缺失") -> 无数据/数据缺失 | CU188: =IF(CT188<0,0,IF(CT188="无数据/数据缺失",0%,IF(CT188>'基本数据输入&测算结果'!$C$20,100%,CT188/'基本数据输入&测算结果'!$C$20))) -> 0 | CV188: =IFERROR((AVERAGE(AL188:AS188)*2-'基本数据输入&测算结果'!$C$24*2)/'基本数据输入&测算结果'!$C$21/'基本数据输入&测算结果'!$C$22,"无数据/数据缺失") -> 无数据/数据缺失 | CW188: =IF(CV188<0,0,IF(CV188="无数据/数据缺失",0%,IF(CV188>'基本数据输入&测算结果'!$C$20*CU188,CU188,CV188/'基本数据输入&测算结果'!$C$20*CU188))) -> 0 | CX188: =IFERROR(('基本数据输入&测算结果'!$C$19*2-AVERAGE(AT188:BA188)*2-'基本数据输入&测算结果'!$C$23*2)/'基本数据输入&测算结果'!$C$21*'基本数据输入&测算结果'!$C$22,"无数据/数据缺失") -> 无数据/数据缺失 | CY188: =IF(CX188<0,0,IF(CX188="无数据/数据缺失",0%,IF(CX188>'基本数据输入&测算结果'!$C$20,100%,CX188/'基本数据输入&测算结果'!$C$20))) -> 0 | CZ188: =IFERROR((AVERAGE(BN188:CS188)*8-'基本数据输入&测算结果'!$C$24*8)/'基本数据输入&测算结果'!$C$21/'基本数据输入&测算结果'!$C$22,"无数据/数据缺失") -> 无数据/数据缺失 | DA188: =IF(CZ188<0,0,IF(CZ188="无数据/数据缺失",0,IF('基本数据输入&测算结果'!$C$20*CY188>CZ188,CZ188/'基本数据输入&测算结果'!$C$20*CY188,CY188))) -> 0 | DB188: =MIN(CU188,CW188)+MIN(CY188,DA188) -> 0
A189: 2025-07-07 | CT189: =IFERROR(('基本数据输入&测算结果'!$C$19*7-AVERAGE(J189:AK189)*7-'基本数据输入&测算结果'!$C$23*7)/'基本数据输入&测算结果'!$C$21*'基本数据输入&测算结果'!$C$22,"无数据/数据缺失") -> 无数据/数据缺失 | CU189: =IF(CT189<0,0,IF(CT189="无数据/数据缺失",0%,IF(CT189>'基本数据输入&测算结果'!$C$20,100%,CT189/'基本数据输入&测算结果'!$C$20))) -> 0 | CV189: =IFERROR((AVERAGE(AL189:AS189)*2-'基本数据输入&测算结果'!$C$24*2)/'基本数据输入&测算结果'!$C$21/'基本数据输入&测算结果'!$C$22,"无数据/数据缺失") -> 无数据/数据缺失 | CW189: =IF(CV189<0,0,IF(CV189="无数据/数据缺失",0%,IF(CV189>'基本数据输入&测算结果'!$C$20*CU189,CU189,CV189/'基本数据输入&测算结果'!$C$20*CU189))) -> 0 | CX189: =IFERROR(('基本数据输入&测算结果'!$C$19*2-AVERAGE(AT189:BA189)*2-'基本数据输入&测算结果'!$C$23*2)/'基本数据输入&测算结果'!$C$21*'基本数据输入&测算结果'!$C$22,"无数据/数据缺失") -> 无数据/数据缺失 | CY189: =IF(CX189<0,0,IF(CX189="无数据/数据缺失",0%,IF(CX189>'基本数据输入&测算结果'!$C$20,100%,CX189/'基本数据输入&测算结果'!$C$20))) -> 0 | CZ189: =IFERROR((AVERAGE(BN189:CS189)*8-'基本数据输入&测算结果'!$C$24*8)/'基本数据输入&测算结果'!$C$21/'基本数据输入&测算结果'!$C$22,"无数据/数据缺失") -> 无数据/数据缺失 | DA189: =IF(CZ189<0,0,IF(CZ189="无数据/数据缺失",0,IF('基本数据输入&测算结果'!$C$20*CY189>CZ189,CZ189/'基本数据输入&测算结果'!$C$20*CY189,CY189))) -> 0 | DB189: =MIN(CU189,CW189)+MIN(CY189,DA189) -> 0
A190: 2025-07-08 | CT190: =IFERROR(('基本数据输入&测算结果'!$C$19*7-AVERAGE(J190:AK190)*7-'基本数据输入&测算结果'!$C$23*7)/'基本数据输入&测算结果'!$C$21*'基本数据输入&测算结果'!$C$22,"无数据/数据缺失") -> 无数据/数据缺失 | CU190: =IF(CT190<0,0,IF(CT190="无数据/数据缺失",0%,IF(CT190>'基本数据输入&测算结果'!$C$20,100%,CT190/'基本数据输入&测算结果'!$C$20))) -> 0 | CV190: =IFERROR((AVERAGE(AL190:AS190)*2-'基本数据输入&测算结果'!$C$24*2)/'基本数据输入&测算结果'!$C$21/'基本数据输入&测算结果'!$C$22,"无数据/数据缺失") -> 无数据/数据缺失 | CW190: =IF(CV190<0,0,IF(CV190="无数据/数据缺失",0%,IF(CV190>'基本数据输入&测算结果'!$C$20*CU190,CU190,CV190/'基本数据输入&测算结果'!$C$20*CU190))) -> 0 | CX190: =IFERROR(('基本数据输入&测算结果'!$C$19*2-AVERAGE(AT190:BA190)*2-'基本数据输入&测算结果'!$C$23*2)/'基本数据输入&测算结果'!$C$21*'基本数据输入&测算结果'!$C$22,"无数据/数据缺失") -> 无数据/数据缺失 | CY190: =IF(CX190<0,0,IF(CX190="无数据/数据缺失",0%,IF(CX190>'基本数据输入&测算结果'!$C$20,100%,CX190/'基本数据输入&测算结果'!$C$20))) -> 0 | CZ190: =IFERROR((AVERAGE(BN190:CS190)*8-'基本数据输入&测算结果'!$C$24*8)/'基本数据输入&测算结果'!$C$21/'基本数据输入&测算结果'!$C$22,"无数据/数据缺失") -> 无数据/数据缺失 | DA190: =IF(CZ190<0,0,IF(CZ190="无数据/数据缺失",0,IF('基本数据输入&测算结果'!$C$20*CY190>CZ190,CZ190/'基本数据输入&测算结果'!$C$20*CY190,CY190))) -> 0 | DB190: =MIN(CU190,CW190)+MIN(CY190,DA190) -> 0
A191: 2025-07-09 | CT191: =IFERROR(('基本数据输入&测算结果'!$C$19*7-AVERAGE(J191:AK191)*7-'基本数据输入&测算结果'!$C$23*7)/'基本数据输入&测算结果'!$C$21*'基本数据输入&测算结果'!$C$22,"无数据/数据缺失") -> 无数据/数据缺失 | CU191: =IF(CT191<0,0,IF(CT191="无数据/数据缺失",0%,IF(CT191>'基本数据输入&测算结果'!$C$20,100%,CT191/'基本数据输入&测算结果'!$C$20))) -> 0 | CV191: =IFERROR((AVERAGE(AL191:AS191)*2-'基本数据输入&测算结果'!$C$24*2)/'基本数据输入&测算结果'!$C$21/'基本数据输入&测算结果'!$C$22,"无数据/数据缺失") -> 无数据/数据缺失 | CW191: =IF(CV191<0,0,IF(CV191="无数据/数据缺失",0%,IF(CV191>'基本数据输入&测算结果'!$C$20*CU191,CU191,CV191/'基本数据输入&测算结果'!$C$20*CU191))) -> 0 | CX191: =IFERROR(('基本数据输入&测算结果'!$C$19*2-AVERAGE(AT191:BA191)*2-'基本数据输入&测算结果'!$C$23*2)/'基本数据输入&测算结果'!$C$21*'基本数据输入&测算结果'!$C$22,"无数据/数据缺失") -> 无数据/数据缺失 | CY191: =IF(CX191<0,0,IF(CX191="无数据/数据缺失",0%,IF(CX191>'基本数据输入&测算结果'!$C$20,100%,CX191/'基本数据输入&测算结果'!$C$20))) -> 0 | CZ191: =IFERROR((AVERAGE(BN191:CS191)*8-'基本数据输入&测算结果'!$C$24*8)/'基本数据输入&测算结果'!$C$21/'基本数据输入&测算结果'!$C$22,"无数据/数据缺失") -> 无数据/数据缺失 | DA191: =IF(CZ191<0,0,IF(CZ191="无数据/数据缺失",0,IF('基本数据输入&测算结果'!$C$20*CY191>CZ191,CZ191/'基本数据输入&测算结果'!$C$20*CY191,CY191))) -> 0 | DB191: =MIN(CU191,CW191)+MIN(CY191,DA191) -> 0
A192: 2025-07-10 | CT192: =IFERROR(('基本数据输入&测算结果'!$C$19*7-AVERAGE(J192:AK192)*7-'基本数据输入&测算结果'!$C$23*7)/'基本数据输入&测算结果'!$C$21*'基本数据输入&测算结果'!$C$22,"无数据/数据缺失") -> 无数据/数据缺失 | CU192: =IF(CT192<0,0,IF(CT192="无数据/数据缺失",0%,IF(CT192>'基本数据输入&测算结果'!$C$20,100%,CT192/'基本数据输入&测算结果'!$C$20))) -> 0 | CV192: =IFERROR((AVERAGE(AL192:AS192)*2-'基本数据输入&测算结果'!$C$24*2)/'基本数据输入&测算结果'!$C$21/'基本数据输入&测算结果'!$C$22,"无数据/数据缺失") -> 无数据/数据缺失 | CW192: =IF(CV192<0,0,IF(CV192="无数据/数据缺失",0%,IF(CV192>'基本数据输入&测算结果'!$C$20*CU192,CU192,CV192/'基本数据输入&测算结果'!$C$20*CU192))) -> 0 | CX192: =IFERROR(('基本数据输入&测算结果'!$C$19*2-AVERAGE(AT192:BA192)*2-'基本数据输入&测算结果'!$C$23*2)/'基本数据输入&测算结果'!$C$21*'基本数据输入&测算结果'!$C$22,"无数据/数据缺失") -> 无数据/数据缺失 | CY192: =IF(CX192<0,0,IF(CX192="无数据/数据缺失",0%,IF(CX192>'基本数据输入&测算结果'!$C$20,100%,CX192/'基本数据输入&测算结果'!$C$20))) -> 0 | CZ192: =IFERROR((AVERAGE(BN192:CS192)*8-'基本数据输入&测算结果'!$C$24*8)/'基本数据输入&测算结果'!$C$21/'基本数据输入&测算结果'!$C$22,"无数据/数据缺失") -> 无数据/数据缺失 | DA192: =IF(CZ192<0,0,IF(CZ192="无数据/数据缺失",0,IF('基本数据输入&测算结果'!$C$20*CY192>CZ192,CZ192/'基本数据输入&测算结果'!$C$20*CY192,CY192))) -> 0 | DB192: =MIN(CU192,CW192)+MIN(CY192,DA192) -> 0
A193: 2025-07-11 | CT193: =IFERROR(('基本数据输入&测算结果'!$C$19*7-AVERAGE(J193:AK193)*7-'基本数据输入&测算结果'!$C$23*7)/'基本数据输入&测算结果'!$C$21*'基本数据输入&测算结果'!$C$22,"无数据/数据缺失") -> 无数据/数据缺失 | CU193: =IF(CT193<0,0,IF(CT193="无数据/数据缺失",0%,IF(CT193>'基本数据输入&测算结果'!$C$20,100%,CT193/'基本数据输入&测算结果'!$C$20))) -> 0 | CV193: =IFERROR((AVERAGE(AL193:AS193)*2-'基本数据输入&测算结果'!$C$24*2)/'基本数据输入&测算结果'!$C$21/'基本数据输入&测算结果'!$C$22,"无数据/数据缺失") -> 无数据/数据缺失 | CW193: =IF(CV193<0,0,IF(CV193="无数据/数据缺失",0%,IF(CV193>'基本数据输入&测算结果'!$C$20*CU193,CU193,CV193/'基本数据输入&测算结果'!$C$20*CU193))) -> 0 | CX193: =IFERROR(('基本数据输入&测算结果'!$C$19*2-AVERAGE(AT193:BA193)*2-'基本数据输入&测算结果'!$C$23*2)/'基本数据输入&测算结果'!$C$21*'基本数据输入&测算结果'!$C$22,"无数据/数据缺失") -> 无数据/数据缺失 | CY193: =IF(CX193<0,0,IF(CX193="无数据/数据缺失",0%,IF(CX193>'基本数据输入&测算结果'!$C$20,100%,CX193/'基本数据输入&测算结果'!$C$20))) -> 0 | CZ193: =IFERROR((AVERAGE(BN193:CS193)*8-'基本数据输入&测算结果'!$C$24*8)/'基本数据输入&测算结果'!$C$21/'基本数据输入&测算结果'!$C$22,"无数据/数据缺失") -> 无数据/数据缺失 | DA193: =IF(CZ193<0,0,IF(CZ193="无数据/数据缺失",0,IF('基本数据输入&测算结果'!$C$20*CY193>CZ193,CZ193/'基本数据输入&测算结果'!$C$20*CY193,CY193))) -> 0 | DB193: =MIN(CU193,CW193)+MIN(CY193,DA193) -> 0
A194: 2025-07-12 | CT194: =IFERROR(('基本数据输入&测算结果'!$C$19*7-AVERAGE(J194:AK194)*7-'基本数据输入&测算结果'!$C$23*7)/'基本数据输入&测算结果'!$C$21*'基本数据输入&测算结果'!$C$22,"无数据/数据缺失") -> 无数据/数据缺失 | CU194: =IF(CT194<0,0,IF(CT194="无数据/数据缺失",0%,IF(CT194>'基本数据输入&测算结果'!$C$20,100%,CT194/'基本数据输入&测算结果'!$C$20))) -> 0 | CV194: =IFERROR((AVERAGE(AL194:AS194)*2-'基本数据输入&测算结果'!$C$24*2)/'基本数据输入&测算结果'!$C$21/'基本数据输入&测算结果'!$C$22,"无数据/数据缺失") -> 无数据/数据缺失 | CW194: =IF(CV194<0,0,IF(CV194="无数据/数据缺失",0%,IF(CV194>'基本数据输入&测算结果'!$C$20*CU194,CU194,CV194/'基本数据输入&测算结果'!$C$20*CU194))) -> 0 | CX194: =IFERROR(('基本数据输入&测算结果'!$C$19*2-AVERAGE(AT194:BA194)*2-'基本数据输入&测算结果'!$C$23*2)/'基本数据输入&测算结果'!$C$21*'基本数据输入&测算结果'!$C$22,"无数据/数据缺失") -> 无数据/数据缺失 | CY194: =IF(CX194<0,0,IF(CX194="无数据/数据缺失",0%,IF(CX194>'基本数据输入&测算结果'!$C$20,100%,CX194/'基本数据输入&测算结果'!$C$20))) -> 0 | CZ194: =IFERROR((AVERAGE(BN194:CS194)*8-'基本数据输入&测算结果'!$C$24*8)/'基本数据输入&测算结果'!$C$21/'基本数据输入&测算结果'!$C$22,"无数据/数据缺失") -> 无数据/数据缺失 | DA194: =IF(CZ194<0,0,IF(CZ194="无数据/数据缺失",0,IF('基本数据输入&测算结果'!$C$20*CY194>CZ194,CZ194/'基本数据输入&测算结果'!$C$20*CY194,CY194))) -> 0 | DB194: =MIN(CU194,CW194)+MIN(CY194,DA194) -> 0
...

Sheet 经济测算
A1: 月份 | B1: 尖电价/元 | C1: 峰电价/元 | D1: 平电价/元 | E1: 谷电价/元 | F1: 设备容量/度 | G1: 电差类型 | H1: 放电深度 | I1: 单充/放效率 | J1: 计算天数 | K1: 收益/万元 | L1: 日均收益 | M1: 日均度电收益 | N1: 放电度电收益 | O1: 上午尖电价比例（如有） | P1: 下午尖电价比例（如有） | Q1: 上午充电率 | R1: 上午放电率 | S1: 下午充电率 | T1: 下午放电率
A2: 45658 | B2: 1.27541 | C2: 1.07497 | D2: 0.61657 | E2: 0.28052 | F2: ='基本数据输入&测算结果'!$C$20 -> 500 | G2: 平谷+峰谷、尖谷 | H2: 0.9 | I2: 0.922 | J2: =SUM('负荷数据&测算'!DB2:DB32)/2 -> 1 | K2: =((F2*H2*I2*D2*J2-F2*H2/I2*E2*J2)+(F2*H2*I2*B2*P2*J2+F2*H2*I2*C2*(1-P2)*J2-F2*H2/I2*E2*J2))/10000 -> 0.043067614 | L2: =K2/J2 -> 0.043067614 | M2: =L2*10000/F2 -> 0.86135229 | N2: =K2/(F2*H2*I2*2*J2)*10000 -> 0.51901198 | O2: ='基本数据输入&测算结果'!R19 -> 0 | P2: ='基本数据输入&测算结果'!S19 -> 0.032258065 | Q2: ='基本数据输入&测算结果'!G19 -> 0.032258065 | R2: ='基本数据输入&测算结果'!K19 -> 0.032258065 | S2: ='基本数据输入&测算结果'!H19 -> 0.032258065 | T2: ='基本数据输入&测算结果'!L19 -> 0.032258065
A3: 45689 | C3: 0.95171 | D3: 0.55992 | E3: 0.23272 | F3: ='基本数据输入&测算结果'!$C$20 -> 500 | G3: 峰谷 | H3: 0.9 | I3: 0.922 | J3: =SUM('负荷数据&测算'!DB33:DB60)/2 -> 0 | K3: =((F3*H3*I3*B3*O3*J3+F3*H3*I3*C3*(1-O3)*J3-F3*H3/I3*E3*J3)+(F3*H3*I3*B3*P3*J3+F3*H3*I3*C3*(1-P3)*J3-F3*H3/I3*E3*J3))/10000 -> 0 | L3: =K3/J3 -> #DIV/0! | M3: =L3*10000/F3 -> #DIV/0! | N3: =K3/(F3*H3*I3*2*J3)*10000 -> #DIV/0! | O3: ='基本数据输入&测算结果'!R20 -> 0 | P3: ='基本数据输入&测算结果'!S20 -> 0 | Q3: ='基本数据输入&测算结果'!G20 -> 0 | R3: ='基本数据输入&测算结果'!K20 -> 0 | S3: ='基本数据输入&测算结果'!H20 -> 0 | T3: ='基本数据输入&测算结果'!L20 -> 0
A4: 45717 | C4: 1.04206 | D4: 0.63966 | E4: 0.30361 | F4: ='基本数据输入&测算结果'!$C$20 -> 500 | G4: 峰谷 | H4: 0.9 | I4: 0.922 | J4: =SUM('负荷数据&测算'!DB61:DB91)/2 -> 0 | K4: =((F4*H4*I4*B4*O4*J4+F4*H4*I4*C4*(1-O4)*J4-F4*H4/I4*E4*J4)+(F4*H4*I4*B4*P4*J4+F4*H4*I4*C4*(1-P4)*J4-F4*H4/I4*E4*J4))/10000 -> 0 | L4: =K4/J4 -> #DIV/0! | M4: =L4*10000/F4 -> #DIV/0! | N4: =K4/(F4*H4*I4*2*J4)*10000 -> #DIV/0! | O4: ='基本数据输入&测算结果'!R21 -> 0 | P4: ='基本数据输入&测算结果'!S21 -> 0 | Q4: ='基本数据输入&测算结果'!G21 -> 0 | R4: ='基本数据输入&测算结果'!K21 -> 0 | S4: ='基本数据输入&测算结果'!H21 -> 0 | T4: ='基本数据输入&测算结果'!L21 -> 0
A5: 45748 | C5: 1.03829 | D5: 0.63589 | E5: 0.29984 | F5: ='基本数据输入&测算结果'!$C$20 -> 500 | G5: 峰谷 | H5: 0.9 | I5: 0.922 | J5: =SUM('负荷数据&测算'!DB92:DB121)/2 -> 0 | K5: =((F5*H5*I5*B5*O5*J5+F5*H5*I5*C5*(1-O5)*J5-F5*H5/I5*E5*J5)+(F5*H5*I5*B5*P5*J5+F5*H5*I5*C5*(1-P5)*J5-F5*H5/I5*E5*J5))/10000 -> 0 | L5: =K5/J5 -> #DIV/0! | M5: =L5*10000/F5 -> #DIV/0! | N5: =K5/(F5*H5*I5*2*J5)*10000 -> #DIV/0! | O5: ='基本数据输入&测算结果'!R22 -> 0 | P5: ='基本数据输入&测算结果'!S22 -> 0 | Q5: ='基本数据输入&测算结果'!G22 -> 0 | R5: ='基本数据输入&测算结果'!K22 -> 0 | S5: ='基本数据输入&测算结果'!H22 -> 0 | T5: ='基本数据输入&测算结果'!L22 -> 0
A6: 45778 | C6: 1.0485 | D6: 0.6461 | E6: 0.31005 | F6: ='基本数据输入&测算结果'!$C$20 -> 500 | G6: 峰谷 | H6: 0.9 | I6: 0.922 | J6: =SUM('负荷数据&测算'!DB122:DB152)/2 -> 0 | K6: =((F6*H6*I6*B6*O6*J6+F6*H6*I6*C6*(1-O6)*J6-F6*H6/I6*E6*J6)+(F6*H6*I6*B6*P6*J6+F6*H6*I6*C6*(1-P6)*J6-F6*H6/I6*E6*J6))/10000 -> 0 | L6: =K6/J6 -> #DIV/0! | M6: =L6*10000/F6 -> #DIV/0! | N6: =K6/(F6*H6*I6*2*J6)*10000 -> #DIV/0! | O6: ='基本数据输入&测算结果'!R23 -> 0 | P6: ='基本数据输入&测算结果'!S23 -> 0 | Q6: ='基本数据输入&测算结果'!G23 -> 0 | R6: ='基本数据输入&测算结果'!K23 -> 0 | S6: ='基本数据输入&测算结果'!H23 -> 0 | T6: ='基本数据输入&测算结果'!L23 -> 0
A7: 45809 | C7: 1.0516 | D7: 0.6492 | E7: 0.31315 | F7: ='基本数据输入&测算结果'!$C$20 -> 500 | G7: 峰谷 | H7: 0.9 | I7: 0.922 | J7: =SUM('负荷数据&测算'!DB153:DB182)/2 -> 0 | K7: =((F7*H7*I7*B7*O7*J7+F7*H7*I7*C7*(1-O7)*J7-F7*H7/I7*E7*J7)+(F7*H7*I7*B7*P7*J7+F7*H7*I7*C7*(1-P7)*J7-F7*H7/I7*E7*J7))/10000 -> 0 | L7: =K7/J7 -> #DIV/0! | M7: =L7*10000/F7 -> #DIV/0! | N7: =K7/(F7*H7*I7*2*J7)*10000 -> #DIV/0! | O7: ='基本数据输入&测算结果'!R24 -> 0 | P7: ='基本数据输入&测算结果'!S24 -> 0 | Q7: ='基本数据输入&测算结果'!G24 -> 0 | R7: ='基本数据输入&测算结果'!K24 -> 0 | S7: ='基本数据输入&测算结果'!H24 -> 0 | T7: ='基本数据输入&测算结果'!L24 -> 0
A8: 45474 | B8: 1.30899 | C8: 1.10855 | D8: 0.65015 | E8: 0.3141 | F8: ='基本数据输入&测算结果'!$C$20 -> 500 | G8: 平谷+峰谷、尖谷 | H8: 0.9 | I8: 0.922 | J8: =SUM('负荷数据&测算'!DB183:DB213)/2 -> 0 | K8: =((F8*H8*I8*D8*J8-F8*H8/I8*E8*J8)+(F8*H8*I8*B8*P8*J8+F8*H8*I8*C8*(1-P8)*J8-F8*H8/I8*E8*J8))/10000 -> 0 | L8: =K8/J8 -> #DIV/0! | M8: =L8*10000/F8 -> #DIV/0! | N8: =K8/(F8*H8*I8*2*J8)*10000 -> #DIV/0! | O8: ='基本数据输入&测算结果'!R25 -> 0 | P8: ='基本数据输入&测算结果'!S25 -> 0 | Q8: ='基本数据输入&测算结果'!G25 -> 0 | R8: ='基本数据输入&测算结果'!K25 -> 0 | S8: =AVERAGE('基本数据输入&测算结果'!H25,'基本数据输入&测算结果'!I25) -> 0 | T8: =AVERAGE('基本数据输入&测算结果'!L25,'基本数据输入&测算结果'!M25) -> 0
A9: 45505 | B9: 1.28332 | C9: 1.07893 | D9: 0.51148 | E9: 0.2688 | F9: ='基本数据输入&测算结果'!$C$20 -> 500 | G9: 平谷+峰谷、尖谷 | H9: 0.9 | I9: 0.922 | J9: =SUM('负荷数据&测算'!DB214:DB244)/2 -> 0 | K9: =((F9*H9*I9*D9*J9-F9*H9/I9*E9*J9)+(F9*H9*I9*B9*P9*J9+F9*H9*I9*C9*(1-P9)*J9-F9*H9/I9*E9*J9))/10000 -> 0 | L9: =K9/J9 -> #DIV/0! | M9: =L9*10000/F9 -> #DIV/0! | N9: =K9/(F9*H9*I9*2*J9)*10000 -> #DIV/0! | O9: ='基本数据输入&测算结果'!R26 -> 0 | P9: ='基本数据输入&测算结果'!S26 -> 0 | Q9: ='基本数据输入&测算结果'!G26 -> 0 | R9: ='基本数据输入&测算结果'!K26 -> 0 | S9: =AVERAGE('基本数据输入&测算结果'!H26,'基本数据输入&测算结果'!I26) -> 0 | T9: =AVERAGE('基本数据输入&测算结果'!L26,'基本数据输入&测算结果'!M26) -> 0
A10: 45536 | C10: 1.11923 | D10: 0.6499 | E10: 0.30583 | F10: ='基本数据输入&测算结果'!$C$20 -> 500 | G10: 平谷+峰谷 | H10: 0.9 | I10: 0.922 | J10: =SUM('负荷数据&测算'!DB245:DB274)/2 -> 0 | K10: =((F10*H10*I10*D10*J10-F10*H10/I10*E10*J10)+(F10*H10*I10*B10*P10*J10+F10*H10*I10*C10*(1-P10)*J10-F10*H10/I10*E10*J10))/10000 -> 0 | L10: =K10/J10 -> #DIV/0! | M10: =L10*10000/F10 -> #DIV/0! | N10: =K10/(F10*H10*I10*2*J10)*10000 -> #DIV/0! | O10: ='基本数据输入&测算结果'!R27 -> 0 | P10: ='基本数据输入&测算结果'!S27 -> 0 | Q10: ='基本数据输入&测算结果'!G27 -> 0 | R10: ='基本数据输入&测算结果'!K27 -> 0 | S10: ='基本数据输入&测算结果'!H27 -> 0 | T10: ='基本数据输入&测算结果'!L27 -> 0
A11: 45566 | C11: 1.05511 | D11: 0.64319 | E11: 0.29918 | F11: ='基本数据输入&测算结果'!$C$20 -> 500 | G11: 峰谷 | H11: 0.9 | I11: 0.922 | J11: =SUM('负荷数据&测算'!DB275:DB305)/2 -> 0 | K11: =((F11*H11*I11*B11*O11*J11+F11*H11*I11*C11*(1-O11)*J11-F11*H11/I11*E11*J11)+(F11*H11*I11*B11*P11*J11+F11*H11*I11*C11*(1-P11)*J11-F11*H11/I11*E11*J11))/10000 -> 0 | L11: =K11/J11 -> #DIV/0! | M11: =L11*10000/F11 -> #DIV/0! | N11: =K11/(F11*H11*I11*2*J11)*10000 -> #DIV/0! | O11: ='基本数据输入&测算结果'!R28 -> 0 | P11: ='基本数据输入&测算结果'!S28 -> 0 | Q11: ='基本数据输入&测算结果'!G28 -> 0 | R11: ='基本数据输入&测算结果'!K28 -> 0 | S11: ='基本数据输入&测算结果'!H28 -> 0 | T11: ='基本数据输入&测算结果'!L28 -> 0
A12: 45597 | C12: 1.03214 | D12: 0.62017 | E12: 0.27613 | F12: ='基本数据输入&测算结果'!$C$20 -> 500 | G12: 峰谷 | H12: 0.9 | I12: 0.922 | J12: =SUM('负荷数据&测算'!DB306:DB335)/2 -> 0 | K12: =((F12*H12*I12*B12*O12*J12+F12*H12*I12*C12*(1-O12)*J12-F12*H12/I12*E12*J12)+(F12*H12*I12*B12*P12*J12+F12*H12*I12*C12*(1-P12)*J12-F12*H12/I12*E12*J12))/10000 -> 0 | L12: =K12/J12 -> #DIV/0! | M12: =L12*10000/F12 -> #DIV/0! | N12: =K12/(F12*H12*I12*2*J12)*10000 -> #DIV/0! | O12: ='基本数据输入&测算结果'!R29 -> 0 | P12: ='基本数据输入&测算结果'!S29 -> 0 | Q12: ='基本数据输入&测算结果'!G29 -> 0 | R12: ='基本数据输入&测算结果'!K29 -> 0 | S12: ='基本数据输入&测算结果'!H29 -> 0 | T12: ='基本数据输入&测算结果'!L29 -> 0
A13: 45627 | B13: 1.2675 | C13: 1.06338 | D13: 0.59655 | E13: 0.25432 | F13: ='基本数据输入&测算结果'!$C$20 -> 500 | G13: 平谷+峰谷、尖谷 | H13: 0.9 | I13: 0.922 | J13: =SUM('负荷数据&测算'!DB336:DB366)/2 -> 0 | K13: =((F13*H13*I13*D13*J13-F13*H13/I13*E13*J13)+(F13*H13*I13*B13*P13*J13+F13*H13*I13*C13*(1-P13)*J13-F13*H13/I13*E13*J13))/10000 -> 0 | L13: =K13/J13 -> #DIV/0! | M13: =L13*10000/F13 -> #DIV/0! | N13: =K13/(F13*H13*I13*2*J13)*10000 -> #DIV/0! | O13: ='基本数据输入&测算结果'!R30 -> 0 | P13: ='基本数据输入&测算结果'!S30 -> 0 | Q13: ='基本数据输入&测算结果'!G30 -> 0 | R13: ='基本数据输入&测算结果'!K30 -> 0 | S13: ='基本数据输入&测算结果'!H30 -> 0 | T13: ='基本数据输入&测算结果'!L30 -> 0
A14: 平均每天收益 | J14: =SUM(J2:J13) -> 1 | K14: =SUM(K2:K13)/J14 -> 0.043067614 | N14: =AVERAGE(N2:N13) -> #DIV/0!
A15: 首年收益 | J15: =INT('基本数据输入&测算结果'!O32)-5 -> -5 | K15: =SUM(K2:K13)*J15/J14 -> -0.21533807
I18: 计算天数 | J18: 电网放电量 | K18: 电网充电量 | L18: 平谷 | M18: 峰谷/尖 | P18: 平谷 | Q18: 峰谷
H19: 45658 | I19: =J2 -> 1 | J19: =F2*H2*I2 -> 414.9 | K19: =F2*H2/I2 -> 488.06941 | L19: =I19*(J19*D2-K19*E2) -> 118.90166 | M19: =I19*(J19*C2*(1-P2)+J19*B2*P2-K19*E2) -> 311.77448 | P19: 1 | Q19: 1 | R19: {=SUMPRODUCT(L19:M19,P19:Q19)/10000} -> 0.043067614
A20: 年份 | B20: 总收益/万元 | C20: 衰减率 | D20: 收益分成 | E20: 投资方收益/万元 | F20: 用户收益/万元 | H20: 45689 | I20: =J3 -> 0 | J20: =F3*H3*I3 -> 414.9 | K20: =F3*H3/I3 -> 488.06941 | L20: =I20*(J20*D3-K20*E3) -> 0 | M20: =I20*(J20*C3*(1-P3)+J20*B3*P3-K20*E3) -> 0 | Q20: 2 | R20: {=SUMPRODUCT(L20:M20,P20:Q20)/10000} -> 0
